Workbook
Name _Toc74834714: DropDown!$O$1
Name AuswahlX: [1]DropDown!$H$2:$H$3
Name AuswahlX: [1]DropDown!$H$2:$H$3
Name AuswahlX: DropDown!$H$2:$H$3
Name Fehlerart: [1]DropDown!$A$2:$A$12
Name Fehlerart: [1]DropDown!$A$2:$A$12
Name Fehlerart: DropDown!$A$4:$A$13
Name KSK_No.: 'D1-D2-D3'!$D$14
Name Product: DropDown!$N$2:$N$3
Name Product: DropDown!$N$2:$N$3
Name sortingaction: 'D1-D2-D3'!$AD$93
Name Sprachen: [1]DropDown!$C$2:$C$15
Name Sprachen: [1]DropDown!$C$2:$C$15
Name Sprachen: DropDown!$C$2:$C$15
Name Syst: #REF!
Name Syst: #REF!
Name Syst: #REF!
Name X: #REF!
Name X: #REF!
Name X: #REF!
Name X: #REF!
Name X: #REF!
Name X: #REF!
Name YesNo: #REF!
Name YesNo: #REF!
Name YesNo: #REF!
Name YesNo: #REF!
Name YesNo: #REF!
Name YesNo: #REF!
Name YN: #REF!
Name YN: #REF!
Name YN: #REF!
Name YN: #REF!
Name YN: #REF!
Name YN: #REF!

Sheet D1-D2-D3
R2: =INDIRECT($J$4&"!C2")&" "&INDIRECT($J$4&"!C7") -> PROBLEM SOLVING SHEET Basic Data-Team-Problem Description-Immediate Action(s) | BN2: =INDIRECT($J$4&"!C3") -> PSS No. | BW2: =AI4 -> 0 | CG2: 4.15.03.00 | CY2: =INDIRECT($J$4&"!C4") -> Page 1: D0-D1-D2-D3
C4: =INDIRECT($J$4&"!C5") -> Language | J4: ENGLISH | AA4: =INDIRECT($J$4&"!C3") -> PSS No. | AZ4: =INDIRECT($J$4&"!C6") -> Fault type
C7: =INDIRECT($J$4&"!C8") -> Kroschu plant | AF7: =INDIRECT($J$4&"!C9") -> Opening date | BU7: Report version | DU7: 1 | DV7: =IF(DW7="","",MAX($DV$6:DV6)+1) -> 1 | DW7: =IF($D14=DropDown!$N$8,DropDown!N5,"") -> Int. KSK-No. | DX7: =VLOOKUP(DU7,$DV$7:$DW$9,2,FALSE) -> Int. KSK-No.
C8: =INDIRECT($J$4&"!C10") -> Customer | AF8: =INDIRECT($J$4&"!C11") -> Project | BU8: =INDIRECT($J$4&"!C12") -> Customer complaint No. | DU8: 2 | DV8: =IF(DW8="","",MAX($DV$6:DV7)+1) | DW8: =IF($D14=DropDown!$N$9,DropDown!N6,"")
DU9: 3 | DV9: =IF(DW9="","",MAX($DV$6:DV8)+1) | DW9: =IF($D14=DropDown!$N$10,DropDown!N7,"")
B11: =INDIRECT($J$4&"!C13") -> Basic Data
D14: KSK | AM14: =DX7 -> Int. KSK-No. | CC14: =INDIRECT($J$4&"!C21") -> Production date/time
DU15: 1 | DV15: =IF(DW15="","",MAX(DV14:DV14)+1) -> 1 | DW15: =IF($CC16=DropDown!$L$15,DropDown!L18,"") -> PSC | DX15: =VLOOKUP(DU15,DV15:DW16,2,FALSE) -> PSC
D16: =INDIRECT($J$4&"!C17") -> Index | AM16: =INDIRECT($J$4&"!C16") -> Lfd./Serial | CC16: Safety-relevant characterisitc | DU16: 2 | DV16: =IF(DW16="","",MAX($DV$14:DV15)+1) | DW16: =IF($CC16=DropDown!$L$16,DropDown!L19,"")
DU17: 3
B18: =INDIRECT($J$4&"!C22") -> D1 - Team
D20: =INDIRECT($J$4&"!C23") -> Coordinator (/Champion) | BL20: =INDIRECT($J$4&"!C26") -> Sponsor
D21: =INDIRECT($J$4&"!C24") -> Name, prename | T21: =INDIRECT($J$4&"!C25") -> Department/function Contact data | BK21: =INDIRECT($J$4&"!C24") -> Name, prename | CD21: =INDIRECT($J$4&"!C25") -> Department/function Contact data
D24: =INDIRECT($J$4&"!C27") -> Members
B33: =INDIRECT($J$4&"!C28") -> D2 - Problem description
D36: =INDIRECT($J$4&"!C29") -> NOK PART | BL36: =INDIRECT($J$4&"!C30") -> OK PART
D46: =INDIRECT($J$4&"!C65") -> Symptom description | AU46: =INDIRECT($J$4&"!C43") -> IS | CG46: =INDIRECT($J$4&"!C44") -> IS NOT
AR47: =INDIRECT($J$4&"!C45") -> What | AU47: =INDIRECT($J$4&"!C49") -> Which product/process does the problem concern ? | CG47: =INDIRECT($J$4&"!C57") -> Are there comparable products/processes where the problem did not occur ?
D48: =INDIRECT($J$4&"!C66") -> Problem description
AU49: =INDIRECT($J$4&"!C50") -> What is the deviation ? | CG49: =INDIRECT($J$4&"!C58") -> Are additional deviations of the affected product/process expected ?
D51: =INDIRECT($J$4&"!C31")&" & "&INDIRECT($J$4&"!C32") -> Fault code & Fault description | AR51: =INDIRECT($J$4&"!C46") -> Where | AU51: =INDIRECT($J$4&"!C51") -> Where was the product/process when the deviation first occurred ? | CG51: =INDIRECT($J$4&"!C59") -> Where else could the deviation occur ?
D52: =VLOOKUP(AH51,'Fault catalogue'!A2:C574,3,0) -> #N/A
AU53: =INDIRECT($J$4&"!C52") -> Where in the product/process did the deviation occur ? | CG53: =INDIRECT($J$4&"!C60") -> What are the names of the neighbouring products/processes and which of them are not affected by the deviation ?
D54: =INDIRECT($J$4&"!C33") -> Fault location
AR55: =INDIRECT($J$4&"!C47") -> When | AU55: =INDIRECT($J$4&"!C53") -> When was the deviation first detected ? (Date of occurrence & life cycle) | CG55: =INDIRECT($J$4&"!C61") -> Can the problem have occurred in an earlier phase/time ?
D56: =INDIRECT($J$4&"!C34") -> Workplace
D57: =INDIRECT($J$4&"!C35") -> Qualification | AU57: =INDIRECT($J$4&"!C54") -> Is there a recognisable systematic of failures ? (single failure, continuous increase/fall, random or cyclical) ? | CG57: =INDIRECT($J$4&"!C62") -> Can additional failures be expected since the discovery ?
D58: =INDIRECT($J$4&"!C36") -> Line
D59: =INDIRECT($J$4&"!C37") -> Team | AR59: =INDIRECT($J$4&"!C48") -> How many | AU59: =INDIRECT($J$4&"!C55") -> How many failures ? (number & PPM's) | CG59: =INDIRECT($J$4&"!C63") -> How many more can be expected in the future ?
D60: =INDIRECT($J$4&"!C38") -> Equipment
D61: =INDIRECT($J$4&"!C39")&":" -> Repetitive fault: | R61: =INDIRECT($J$4&"!C40")&":" -> If yes, PSS No./ 8D No.: | AU61: =INDIRECT($J$4&"!C56") -> Which persons are affected ? What costs have been incurred so far ? Will these rise, fall or remain stable ? | CG61: =INDIRECT($J$4&"!C64") -> What can lead to worse/better circumstances ?
B65: =INDIRECT($J$4&"!C67") -> D3 - Immediate action(s)
BR66: =INDIRECT($J$4&"!C68")&":" -> Status: | CZ66: =INDIRECT($J$4&"!C69") -> Date
D69: =INDIRECT($J$4&"!C70") -> Were the relevant emloyees informed ? | AR69: =INDIRECT($J$4&"!C69") -> Date | BW69: =INDIRECT($J$4&"!C83") -> Responsible
D71: =INDIRECT($J$4&"!C71") -> Limitation of affected products
D73: =INDIRECT($J$4&"!C72") -> Is it possible to do a limitation of the affected products ? | BA73: Yes
T75: =INDIRECT($J$4&"!C73") -> delivered to the customer | AZ75: =INDIRECT($J$4&"!C74") -> on transit | BX75: =INDIRECT($J$4&"!C75") -> at Kroschu
AU77: → | BB77: =SUM(AR75,BP75,CN75) -> 0 | BL77: =INDIRECT($J$4&"!C76") -> total amount of affected products
D79: =INDIRECT($J$4&"!C80") -> Action | CC79: =INDIRECT($J$4&"!C81") -> Effectiveness verification
AZ80: =INDIRECT($J$4&"!C262") -> Start date | BG80: =INDIRECT($J$4&"!C263") -> Closing date | BN80: =INDIRECT($J$4&"!C83") -> Responsible | BX80: =INDIRECT($J$4&"!C82") -> Method | CW80: =INDIRECT($J$4&"!C69") -> Date | DD80: =INDIRECT($J$4&"!C83") -> Responsible | DM80: =INDIRECT($J$4&"!C264") -> Result
...

Sheet Risk assesment (for D3 & D5)
P2: =INDIRECT('D1-D2-D3'!$J$4&"!C2")&"/ "&'8D-Report (with link)'!R2 -> PROBLEM SOLVING SHEET/ 8D-report | AI2: =INDIRECT('D1-D2-D3'!$J$4&"!C3") -> PSS No. | AO2: ='D1-D2-D3'!AI4 -> 0 | AU2: 4.15.03.00 | BC2: =INDIRECT('D1-D2-D3'!$J$4&"!C233") -> Risk assessment
D6: =INDIRECT('D1-D2-D3'!$J$4&"!C234") -> Probability | S6: =INDIRECT('D1-D2-D3'!$J$4&"!C235") -> Effect | AG6: =INDIRECT('D1-D2-D3'!$J$4&"!C246") -> Level | BD6: Matrix
D8: 1 | E8: =INDIRECT('D1-D2-D3'!$J$4&"!C236") -> Remote - Chance for this event is almost 0 | S8: 1 | T8: =INDIRECT('D1-D2-D3'!$J$4&"!C241") -> ignorable - ignorable damages without impact | BB8: =INDIRECT('D1-D2-D3'!$J$4&"!C234") -> Probability | BD8: 5 | BG8: 10 | BJ8: 15 | BM8: 20 | BP8: 25
D9: 2 | E9: =INDIRECT('D1-D2-D3'!$J$4&"!C237") -> Unlikely - Eventaulity exists but is not going to happen | S9: 2 | T9: =INDIRECT('D1-D2-D3'!$J$4&"!C242") -> low - slightly damages outside visible are | AG9: high | AI9: =INDIRECT('D1-D2-D3'!$J$4&"!C247") -> 12 or higher | AM9: =INDIRECT('D1-D2-D3'!$J$4&"!C251") -> measures to be discussed with customer | BD9: 4 | BG9: 8 | BJ9: 12 | BM9: 16 | BP9: 20
D10: 3 | E10: =INDIRECT('D1-D2-D3'!$J$4&"!C238") -> Possible - Event can occurre sometime | S10: 3 | T10: =INDIRECT('D1-D2-D3'!$J$4&"!C243") -> mid - noticable damages in visible area | AG10: mid | AI10: =INDIRECT('D1-D2-D3'!$J$4&"!C248") -> 7 till 11 | AM10: =INDIRECT('D1-D2-D3'!$J$4&"!C252") -> measures upon request of customer | BD10: 3 | BG10: 6 | BJ10: 9 | BM10: 12 | BP10: 15
D11: 4 | E11: =INDIRECT('D1-D2-D3'!$J$4&"!C239") -> Probable - Event will happen sometimes and can be expected | S11: 4 | T11: =INDIRECT('D1-D2-D3'!$J$4&"!C244") -> high - damage with functional impact | AG11: ALARP | AI11: =INDIRECT('D1-D2-D3'!$J$4&"!C249") -> 5 till 6 | AM11: =INDIRECT('D1-D2-D3'!$J$4&"!C253") -> as low as reasonable practicable | BD11: 2 | BG11: 4 | BJ11: 6 | BM11: 8 | BP11: 10
D12: 5 | E12: =INDIRECT('D1-D2-D3'!$J$4&"!C240") -> Almost certain - Event happens often and is expected | S12: 5 | T12: =INDIRECT('D1-D2-D3'!$J$4&"!C245") -> catastrophic - catastrophic damage with consequences | AG12: low | AI12: =INDIRECT('D1-D2-D3'!$J$4&"!C250") -> 1 till 4 | AM12: =INDIRECT('D1-D2-D3'!$J$4&"!C254") -> no further action needed | BD12: 1 | BG12: 2 | BJ12: 3 | BM12: 4 | BP12: 5
BD13: =INDIRECT('D1-D2-D3'!$J$4&"!C235") -> Effect
D17: ='D1-D2-D3'!B65 -> D3 - Immediate action(s) | AE17: =INDIRECT('D1-D2-D3'!$J$4&"!C258") -> Initial evaluation | BE17: =INDIRECT('D1-D2-D3'!$J$4&"!C260") -> New evaluation
U18: =INDIRECT('D1-D2-D3'!$J$4&"!C256") -> Hazard/ Risk | AE18: =INDIRECT('D1-D2-D3'!$J$4&"!C234")&" P" -> Probability P | AI18: =INDIRECT('D1-D2-D3'!$J$4&"!C235")&" E" -> Effect E | AL18: =INDIRECT('D1-D2-D3'!$J$4&"!C257")&" PxE" -> Risk height PxE | AO18: =INDIRECT('D1-D2-D3'!$J$4&"!C246") -> Level | AS18: =INDIRECT('D1-D2-D3'!$J$4&"!C259") -> Measures | BE18: =INDIRECT('D1-D2-D3'!$J$4&"!C234")&" P" -> Probability P | BI18: =INDIRECT('D1-D2-D3'!$J$4&"!C235")&" E" -> Effect E | BL18: =INDIRECT('D1-D2-D3'!$J$4&"!C257")&" PxE" -> Risk height PxE | BO18: =INDIRECT('D1-D2-D3'!$J$4&"!C246") -> Level | BY18: Level 1 | CC18: Level 2
D19: ='D1-D2-D3'!D81 -> Measures for continuing secure production at customer | H19: =IF('D1-D2-D3'!L81="","",'D1-D2-D3'!L81) | K19: =IF('D1-D2-D3'!T81="","",'D1-D2-D3'!T81) | AL19: =BX19 | AO19: =IF(BW19>11,"high",IF(BW19>6,"mid",IF(BW19>4,"ALARP",IF(BW19=0,"",IF(BW19>=1,"low"))))) | BL19: =CB19 | BO19: =CC19 | BW19: =AE19*AI19 -> 0 | BX19: =IF(BW19=0,"",IF(BW19>=1,BW19)) | BY19: =IF(BW19>11,"high",IF(BW19>6,"mid",IF(BW19>4,"ALARP",IF(BW19=0,"",IF(BW19>=1,"low"))))) | CA19: =BE19*BI19 -> 0 | CB19: =IF(CA19=0,"",IF(CA19>=1,CA19)) | CC19: =IF(CA19>11,"high",IF(CA19>6,"mid",IF(CA19>4,"ALARP",IF(CA19=0,"",IF(CA19>=1,"low")))))
H20: =IF('D1-D2-D3'!L82="","",'D1-D2-D3'!L82) | K20: =IF('D1-D2-D3'!T82="","",'D1-D2-D3'!T82) | AL20: =BX20 | AO20: =IF(BW20>11,"high",IF(BW20>6,"mid",IF(BW20>4,"ALARP",IF(BW20=0,"",IF(BW20>=1,"low"))))) | BL20: =CB20 | BO20: =CC20 | BW20: =AE20*AI20 -> 0 | BX20: =IF(BW20=0,"",IF(BW20>=1,BW20)) | BY20: =IF(BW20>11,"high",IF(BW20>6,"mid",IF(BW20>4,"ALARP",IF(BW20=0,"",IF(BW20>=1,"low"))))) | CA20: =BE20*BI20 -> 0 | CB20: =IF(CA20=0,"",IF(CA20>=1,CA20)) | CC20: =IF(CA20>11,"high",IF(CA20>6,"mid",IF(CA20>4,"ALARP",IF(CA20=0,"",IF(CA20>=1,"low")))))
H21: =IF('D1-D2-D3'!L83="","",'D1-D2-D3'!L83) | K21: =IF('D1-D2-D3'!T83="","",'D1-D2-D3'!T83) | AL21: =BX21 | AO21: =IF(BW21>11,"high",IF(BW21>6,"mid",IF(BW21>4,"ALARP",IF(BW21=0,"",IF(BW21>=1,"low"))))) | BL21: =CB21 | BO21: =CC21 | BW21: =AE21*AI21 -> 0 | BX21: =IF(BW21=0,"",IF(BW21>=1,BW21)) | BY21: =IF(BW21>11,"high",IF(BW21>6,"mid",IF(BW21>4,"ALARP",IF(BW21=0,"",IF(BW21>=1,"low"))))) | CA21: =BE21*BI21 -> 0 | CB21: =IF(CA21=0,"",IF(CA21>=1,CA21)) | CC21: =IF(CA21>11,"high",IF(CA21>6,"mid",IF(CA21>4,"ALARP",IF(CA21=0,"",IF(CA21>=1,"low")))))
D22: ='D1-D2-D3'!D84 -> Measures for continuing delivery | H22: =IF('D1-D2-D3'!L84="","",'D1-D2-D3'!L84) | K22: =IF('D1-D2-D3'!T84="","",'D1-D2-D3'!T84) | AL22: =BX22 | AO22: =IF(BW22>11,"high",IF(BW22>6,"mid",IF(BW22>4,"ALARP",IF(BW22=0,"",IF(BW22>=1,"low"))))) | BL22: =CB22 | BO22: =CC22 | BW22: =AE22*AI22 -> 0 | BX22: =IF(BW22=0,"",IF(BW22>=1,BW22)) | BY22: =IF(BW22>11,"high",IF(BW22>6,"mid",IF(BW22>4,"ALARP",IF(BW22=0,"",IF(BW22>=1,"low"))))) | CA22: =BE22*BI22 -> 0 | CB22: =IF(CA22=0,"",IF(CA22>=1,CA22)) | CC22: =IF(CA22>11,"high",IF(CA22>6,"mid",IF(CA22>4,"ALARP",IF(CA22=0,"",IF(CA22>=1,"low")))))
H23: =IF('D1-D2-D3'!L85="","",'D1-D2-D3'!L85) | K23: =IF('D1-D2-D3'!T85="","",'D1-D2-D3'!T85) | AL23: =BX23 | AO23: =IF(BW23>11,"high",IF(BW23>6,"mid",IF(BW23>4,"ALARP",IF(BW23=0,"",IF(BW23>=1,"low"))))) | BL23: =CB23 | BO23: =CC23 | BW23: =AE23*AI23 -> 0 | BX23: =IF(BW23=0,"",IF(BW23>=1,BW23)) | BY23: =IF(BW23>11,"high",IF(BW23>6,"mid",IF(BW23>4,"ALARP",IF(BW23=0,"",IF(BW23>=1,"low"))))) | CA23: =BE23*BI23 -> 0 | CB23: =IF(CA23=0,"",IF(CA23>=1,CA23)) | CC23: =IF(CA23>11,"high",IF(CA23>6,"mid",IF(CA23>4,"ALARP",IF(CA23=0,"",IF(CA23>=1,"low")))))
H24: =IF('D1-D2-D3'!L86="","",'D1-D2-D3'!L86) | K24: =IF('D1-D2-D3'!T86="","",'D1-D2-D3'!T86) | AL24: =BX24 | AO24: =IF(BW24>11,"high",IF(BW24>6,"mid",IF(BW24>4,"ALARP",IF(BW24=0,"",IF(BW24>=1,"low"))))) | BL24: =CB24 | BO24: =CC24 | BW24: =AE24*AI24 -> 0 | BX24: =IF(BW24=0,"",IF(BW24>=1,BW24)) | BY24: =IF(BW24>11,"high",IF(BW24>6,"mid",IF(BW24>4,"ALARP",IF(BW24=0,"",IF(BW24>=1,"low"))))) | CA24: =BE24*BI24 -> 0 | CB24: =IF(CA24=0,"",IF(CA24>=1,CA24)) | CC24: =IF(CA24>11,"high",IF(CA24>6,"mid",IF(CA24>4,"ALARP",IF(CA24=0,"",IF(CA24>=1,"low")))))
D25: ='D1-D2-D3'!D87 -> Measures for continuing Kroschu-production | H25: =IF('D1-D2-D3'!L87="","",'D1-D2-D3'!L87) | K25: =IF('D1-D2-D3'!T87="","",'D1-D2-D3'!T87) | AL25: =BX25 | AO25: =IF(BW25>11,"high",IF(BW25>6,"mid",IF(BW25>4,"ALARP",IF(BW25=0,"",IF(BW25>=1,"low"))))) | BL25: =CB25 | BO25: =CC25 | BW25: =AE25*AI25 -> 0 | BX25: =IF(BW25=0,"",IF(BW25>=1,BW25)) | BY25: =IF(BW25>11,"high",IF(BW25>6,"mid",IF(BW25>4,"ALARP",IF(BW25=0,"",IF(BW25>=1,"low"))))) | CA25: =BE25*BI25 -> 0 | CB25: =IF(CA25=0,"",IF(CA25>=1,CA25)) | CC25: =IF(CA25>11,"high",IF(CA25>6,"mid",IF(CA25>4,"ALARP",IF(CA25=0,"",IF(CA25>=1,"low")))))
H26: =IF('D1-D2-D3'!L88="","",'D1-D2-D3'!L88) | K26: =IF('D1-D2-D3'!T88="","",'D1-D2-D3'!T88) | AL26: =BX26 | AO26: =IF(BW26>11,"high",IF(BW26>6,"mid",IF(BW26>4,"ALARP",IF(BW26=0,"",IF(BW26>=1,"low"))))) | BL26: =CB26 | BO26: =CC26 | BW26: =AE26*AI26 -> 0 | BX26: =IF(BW26=0,"",IF(BW26>=1,BW26)) | BY26: =IF(BW26>11,"high",IF(BW26>6,"mid",IF(BW26>4,"ALARP",IF(BW26=0,"",IF(BW26>=1,"low"))))) | CA26: =BE26*BI26 -> 0 | CB26: =IF(CA26=0,"",IF(CA26>=1,CA26)) | CC26: =IF(CA26>11,"high",IF(CA26>6,"mid",IF(CA26>4,"ALARP",IF(CA26=0,"",IF(CA26>=1,"low")))))
H27: =IF('D1-D2-D3'!L89="","",'D1-D2-D3'!L89) | K27: =IF('D1-D2-D3'!T89="","",'D1-D2-D3'!T89) | AL27: =BX27 | AO27: =IF(BW27>11,"high",IF(BW27>6,"mid",IF(BW27>4,"ALARP",IF(BW27=0,"",IF(BW27>=1,"low"))))) | BL27: =CB27 | BO27: =CC27 | BW27: =AE27*AI27 -> 0 | BX27: =IF(BW27=0,"",IF(BW27>=1,BW27)) | BY27: =IF(BW27>11,"high",IF(BW27>6,"mid",IF(BW27>4,"ALARP",IF(BW27=0,"",IF(BW27>=1,"low"))))) | CA27: =BE27*BI27 -> 0 | CB27: =IF(CA27=0,"",IF(CA27>=1,CA27)) | CC27: =IF(CA27>11,"high",IF(CA27>6,"mid",IF(CA27>4,"ALARP",IF(CA27=0,"",IF(CA27>=1,"low")))))
D29: ='D4.5Why''s-D5-D6'!AB6 -> D5 - Corrective Action(s)
BW30: P*C | BX30: Result ohne 0 | BY30: LEVEL | CA30: new evaluat | CC30: L | CF30: Risk | CG30: Level | CH30: Measures
D31: =INDIRECT('D1-D2-D3'!$J$4&"!C137") -> Technical consideration | E31: =IF(ISNA('D4.5Why''s-D5-D6'!BY19),"",'D4.5Why''s-D5-D6'!BY19) | AL31: =BX31 | AO31: =IF(BW31>11,"high",IF(BW31>6,"mid",IF(BW31>4,"ALARP",IF(BW31=0,"",IF(BW31>=1,"low"))))) | BL31: =CB31 | BO31: =CC31 | BW31: =AE31*AI31 -> 0 | BX31: =IF(BW31=0,"",IF(BW31>=1,BW31)) | BY31: =IF(BW31>11,"high",IF(BW31>6,"mid",IF(BW31>4,"ALARP",IF(BW31=0,"",IF(BW31>=1,"low"))))) | CA31: =BE31*BI31 -> 0 | CB31: =IF(CA31=0,"",IF(CA31>=1,CA31)) | CC31: =IF(CA31>11,"high",IF(CA31>6,"mid",IF(CA31>4,"ALARP",IF(CA31=0,"",IF(CA31>=1,"low"))))) | CF31: =IF(U31=0,"",IF(ISNA(U31),"",IF(E31<>"",U31,""))) | CG31: =IF(AO31=0,"",IF(ISNA(AO31),"",IF(E31<>"",AO31,""))) | CH31: =IF(AS31=0,"",IF(ISNA(AS31),"",IF(E31<>"",AS31,"")))
E32: =IF(ISNA('D4.5Why''s-D5-D6'!BY20),"",'D4.5Why''s-D5-D6'!BY20) | AL32: =BX32 | AO32: =IF(BW32>11,"high",IF(BW32>6,"mid",IF(BW32>4,"ALARP",IF(BW32=0,"",IF(BW32>=1,"low"))))) | BL32: =CB32 | BO32: =CC32 | BW32: =AE32*AI32 -> 0 | BX32: =IF(BW32=0,"",IF(BW32>=1,BW32)) | BY32: =IF(BW32>11,"high",IF(BW32>6,"mid",IF(BW32>4,"ALARP",IF(BW32=0,"",IF(BW32>=1,"low"))))) | CA32: =BE32*BI32 -> 0 | CB32: =IF(CA32=0,"",IF(CA32>=1,CA32)) | CC32: =IF(CA32>11,"high",IF(CA32>6,"mid",IF(CA32>4,"ALARP",IF(CA32=0,"",IF(CA32>=1,"low"))))) | CF32: =IF(U32=0,"",IF(ISNA(U32),"",IF(E32<>"",U32,""))) | CG32: =IF(AO32=0,"",IF(ISNA(AO32),"",IF(E32<>"",AO32,""))) | CH32: =IF(AS32=0,"",IF(ISNA(AS32),"",IF(E32<>"",AS32,"")))
E33: =IF(ISNA('D4.5Why''s-D5-D6'!BY21),"",'D4.5Why''s-D5-D6'!BY21) | AL33: =BX33 | AO33: =IF(BW33>11,"high",IF(BW33>6,"mid",IF(BW33>4,"ALARP",IF(BW33=0,"",IF(BW33>=1,"low"))))) | BL33: =CB33 | BO33: =CC33 | BW33: =AE33*AI33 -> 0 | BX33: =IF(BW33=0,"",IF(BW33>=1,BW33)) | BY33: =IF(BW33>11,"high",IF(BW33>6,"mid",IF(BW33>4,"ALARP",IF(BW33=0,"",IF(BW33>=1,"low"))))) | CA33: =BE33*BI33 -> 0 | CB33: =IF(CA33=0,"",IF(CA33>=1,CA33)) | CC33: =IF(CA33>11,"high",IF(CA33>6,"mid",IF(CA33>4,"ALARP",IF(CA33=0,"",IF(CA33>=1,"low"))))) | CF33: =IF(U33=0,"",IF(ISNA(U33),"",IF(E33<>"",U33,""))) | CG33: =IF(AO33=0,"",IF(ISNA(AO33),"",IF(E33<>"",AO33,""))) | CH33: =IF(AS33=0,"",IF(ISNA(AS33),"",IF(E33<>"",AS33,"")))
E34: =IF(ISNA('D4.5Why''s-D5-D6'!BY22),"",'D4.5Why''s-D5-D6'!BY22) | AL34: =BX34 | AO34: =IF(BW34>11,"high",IF(BW34>6,"mid",IF(BW34>4,"ALARP",IF(BW34=0,"",IF(BW34>=1,"low"))))) | BL34: =CB34 | BO34: =CC34 | BW34: =AE34*AI34 -> 0 | BX34: =IF(BW34=0,"",IF(BW34>=1,BW34)) | BY34: =IF(BW34>11,"high",IF(BW34>6,"mid",IF(BW34>4,"ALARP",IF(BW34=0,"",IF(BW34>=1,"low"))))) | CA34: =BE34*BI34 -> 0 | CB34: =IF(CA34=0,"",IF(CA34>=1,CA34)) | CC34: =IF(CA34>11,"high",IF(CA34>6,"mid",IF(CA34>4,"ALARP",IF(CA34=0,"",IF(CA34>=1,"low"))))) | CF34: =IF(U34=0,"",IF(ISNA(U34),"",IF(E34<>"",U34,""))) | CG34: =IF(AO34=0,"",IF(ISNA(AO34),"",IF(E34<>"",AO34,""))) | CH34: =IF(AS34=0,"",IF(ISNA(AS34),"",IF(E34<>"",AS34,"")))
E35: =IF(ISNA('D4.5Why''s-D5-D6'!BY23),"",'D4.5Why''s-D5-D6'!BY23) | AL35: =BX35 | AO35: =IF(BW35>11,"high",IF(BW35>6,"mid",IF(BW35>4,"ALARP",IF(BW35=0,"",IF(BW35>=1,"low"))))) | BL35: =CB35 | BO35: =CC35 | BW35: =AE35*AI35 -> 0 | BX35: =IF(BW35=0,"",IF(BW35>=1,BW35)) | BY35: =IF(BW35>11,"high",IF(BW35>6,"mid",IF(BW35>4,"ALARP",IF(BW35=0,"",IF(BW35>=1,"low"))))) | CA35: =BE35*BI35 -> 0 | CB35: =IF(CA35=0,"",IF(CA35>=1,CA35)) | CC35: =IF(CA35>11,"high",IF(CA35>6,"mid",IF(CA35>4,"ALARP",IF(CA35=0,"",IF(CA35>=1,"low"))))) | CF35: =IF(U35=0,"",IF(ISNA(U35),"",IF(E35<>"",U35,""))) | CG35: =IF(AO35=0,"",IF(ISNA(AO35),"",IF(E35<>"",AO35,""))) | CH35: =IF(AS35=0,"",IF(ISNA(AS35),"",IF(E35<>"",AS35,"")))
E36: =IF(ISNA('D4.5Why''s-D5-D6'!BY24),"",'D4.5Why''s-D5-D6'!BY24) | AL36: =BX36 | AO36: =IF(BW36>11,"high",IF(BW36>6,"mid",IF(BW36>4,"ALARP",IF(BW36=0,"",IF(BW36>=1,"low"))))) | BL36: =CB36 | BO36: =CC36 | BW36: =AE36*AI36 -> 0 | BX36: =IF(BW36=0,"",IF(BW36>=1,BW36)) | BY36: =IF(BW36>11,"high",IF(BW36>6,"mid",IF(BW36>4,"ALARP",IF(BW36=0,"",IF(BW36>=1,"low"))))) | CA36: =BE36*BI36 -> 0 | CB36: =IF(CA36=0,"",IF(CA36>=1,CA36)) | CC36: =IF(CA36>11,"high",IF(CA36>6,"mid",IF(CA36>4,"ALARP",IF(CA36=0,"",IF(CA36>=1,"low"))))) | CF36: =IF(U36=0,"",IF(ISNA(U36),"",IF(E36<>"",U36,""))) | CG36: =IF(AO36=0,"",IF(ISNA(AO36),"",IF(E36<>"",AO36,""))) | CH36: =IF(AS36=0,"",IF(ISNA(AS36),"",IF(E36<>"",AS36,"")))
E37: =IF(ISNA('D4.5Why''s-D5-D6'!BY25),"",'D4.5Why''s-D5-D6'!BY25) | AL37: =BX37 | AO37: =IF(BW37>11,"high",IF(BW37>6,"mid",IF(BW37>4,"ALARP",IF(BW37=0,"",IF(BW37>=1,"low"))))) | BL37: =CB37 | BO37: =CC37 | BW37: =AE37*AI37 -> 0 | BX37: =IF(BW37=0,"",IF(BW37>=1,BW37)) | BY37: =IF(BW37>11,"high",IF(BW37>6,"mid",IF(BW37>4,"ALARP",IF(BW37=0,"",IF(BW37>=1,"low"))))) | CA37: =BE37*BI37 -> 0 | CB37: =IF(CA37=0,"",IF(CA37>=1,CA37)) | CC37: =IF(CA37>11,"high",IF(CA37>6,"mid",IF(CA37>4,"ALARP",IF(CA37=0,"",IF(CA37>=1,"low"))))) | CF37: =IF(U37=0,"",IF(ISNA(U37),"",IF(E37<>"",U37,""))) | CG37: =IF(AO37=0,"",IF(ISNA(AO37),"",IF(E37<>"",AO37,""))) | CH37: =IF(AS37=0,"",IF(ISNA(AS37),"",IF(E37<>"",AS37,"")))
E38: =IF(ISNA('D4.5Why''s-D5-D6'!BY26),"",'D4.5Why''s-D5-D6'!BY26) | AL38: =BX38 | AO38: =IF(BW38>11,"high",IF(BW38>6,"mid",IF(BW38>4,"ALARP",IF(BW38=0,"",IF(BW38>=1,"low"))))) | BL38: =CB38 | BO38: =CC38 | BW38: =AE38*AI38 -> 0 | BX38: =IF(BW38=0,"",IF(BW38>=1,BW38)) | BY38: =IF(BW38>11,"high",IF(BW38>6,"mid",IF(BW38>4,"ALARP",IF(BW38=0,"",IF(BW38>=1,"low"))))) | CA38: =BE38*BI38 -> 0 | CB38: =IF(CA38=0,"",IF(CA38>=1,CA38)) | CC38: =IF(CA38>11,"high",IF(CA38>6,"mid",IF(CA38>4,"ALARP",IF(CA38=0,"",IF(CA38>=1,"low"))))) | CF38: =IF(U38=0,"",IF(ISNA(U38),"",IF(E38<>"",U38,""))) | CG38: =IF(AO38=0,"",IF(ISNA(AO38),"",IF(E38<>"",AO38,""))) | CH38: =IF(AS38=0,"",IF(ISNA(AS38),"",IF(E38<>"",AS38,"")))
E39: =IF(ISNA('D4.5Why''s-D5-D6'!BY27),"",'D4.5Why''s-D5-D6'!BY27) | AL39: =BX39 | AO39: =IF(BW39>11,"high",IF(BW39>6,"mid",IF(BW39>4,"ALARP",IF(BW39=0,"",IF(BW39>=1,"low"))))) | BL39: =CB39 | BO39: =CC39 | BW39: =AE39*AI39 -> 0 | BX39: =IF(BW39=0,"",IF(BW39>=1,BW39)) | BY39: =IF(BW39>11,"high",IF(BW39>6,"mid",IF(BW39>4,"ALARP",IF(BW39=0,"",IF(BW39>=1,"low"))))) | CA39: =BE39*BI39 -> 0 | CB39: =IF(CA39=0,"",IF(CA39>=1,CA39)) | CC39: =IF(CA39>11,"high",IF(CA39>6,"mid",IF(CA39>4,"ALARP",IF(CA39=0,"",IF(CA39>=1,"low"))))) | CF39: =IF(U39=0,"",IF(ISNA(U39),"",IF(E39<>"",U39,""))) | CG39: =IF(AO39=0,"",IF(ISNA(AO39),"",IF(E39<>"",AO39,""))) | CH39: =IF(AS39=0,"",IF(ISNA(AS39),"",IF(E39<>"",AS39,"")))
E40: =IF(ISNA('D4.5Why''s-D5-D6'!BY28),"",'D4.5Why''s-D5-D6'!BY28) | AL40: =BX40 | AO40: =IF(BW40>11,"high",IF(BW40>6,"mid",IF(BW40>4,"ALARP",IF(BW40=0,"",IF(BW40>=1,"low"))))) | BL40: =CB40 | BO40: =CC40 | BW40: =AE40*AI40 -> 0 | BX40: =IF(BW40=0,"",IF(BW40>=1,BW40)) | BY40: =IF(BW40>11,"high",IF(BW40>6,"mid",IF(BW40>4,"ALARP",IF(BW40=0,"",IF(BW40>=1,"low"))))) | CA40: =BE40*BI40 -> 0 | CB40: =IF(CA40=0,"",IF(CA40>=1,CA40)) | CC40: =IF(CA40>11,"high",IF(CA40>6,"mid",IF(CA40>4,"ALARP",IF(CA40=0,"",IF(CA40>=1,"low"))))) | CF40: =IF(U40=0,"",IF(ISNA(U40),"",IF(E40<>"",U40,""))) | CG40: =IF(AO40=0,"",IF(ISNA(AO40),"",IF(E40<>"",AO40,""))) | CH40: =IF(AS40=0,"",IF(ISNA(AS40),"",IF(E40<>"",AS40,"")))
D42: =INDIRECT('D1-D2-D3'!$J$4&"!C138") -> Systemic consideration | E42: =IF(ISNA('D4.5Why''s-D5-D6'!BY44),"",'D4.5Why''s-D5-D6'!BY44) | AL42: =BX42 | AO42: =IF(BW42>11,"high",IF(BW42>6,"mid",IF(BW42>4,"ALARP",IF(BW42=0,"",IF(BW42>=1,"low"))))) | BL42: =CB42 | BO42: =CC42 | BW42: =AE42*AI42 -> 0 | BX42: =IF(BW42=0,"",IF(BW42>=1,BW42)) | BY42: =IF(BW42>11,"high",IF(BW42>6,"mid",IF(BW42>4,"ALARP",IF(BW42=0,"",IF(BW42>=1,"low"))))) | CA42: =BE42*BI42 -> 0 | CB42: =IF(CA42=0,"",IF(CA42>=1,CA42)) | CC42: =IF(CA42>11,"high",IF(CA42>6,"mid",IF(CA42>4,"ALARP",IF(CA42=0,"",IF(CA42>=1,"low"))))) | CF42: =IF(U42=0,"",IF(ISNA(U42),"",IF(E42<>"",U42,""))) | CG42: =IF(AO42=0,"",IF(ISNA(AO42),"",IF(E42<>"",AO42,""))) | CH42: =IF(AS42=0,"",IF(ISNA(AS42),"",IF(E42<>"",AS42,"")))
E43: =IF(ISNA('D4.5Why''s-D5-D6'!BY45),"",'D4.5Why''s-D5-D6'!BY45) | AL43: =BX43 | AO43: =IF(BW43>11,"high",IF(BW43>6,"mid",IF(BW43>4,"ALARP",IF(BW43=0,"",IF(BW43>=1,"low"))))) | BL43: =CB43 | BO43: =CC43 | BW43: =AE43*AI43 -> 0 | BX43: =IF(BW43=0,"",IF(BW43>=1,BW43)) | BY43: =IF(BW43>11,"high",IF(BW43>6,"mid",IF(BW43>4,"ALARP",IF(BW43=0,"",IF(BW43>=1,"low"))))) | CA43: =BE43*BI43 -> 0 | CB43: =IF(CA43=0,"",IF(CA43>=1,CA43)) | CC43: =IF(CA43>11,"high",IF(CA43>6,"mid",IF(CA43>4,"ALARP",IF(CA43=0,"",IF(CA43>=1,"low"))))) | CF43: =IF(U43=0,"",IF(ISNA(U43),"",IF(E43<>"",U43,""))) | CG43: =IF(AO43=0,"",IF(ISNA(AO43),"",IF(E43<>"",AO43,""))) | CH43: =IF(AS43=0,"",IF(ISNA(AS43),"",IF(E43<>"",AS43,"")))
E44: =IF(ISNA('D4.5Why''s-D5-D6'!BY46),"",'D4.5Why''s-D5-D6'!BY46) | AL44: =BX44 | AO44: =IF(BW44>11,"high",IF(BW44>6,"mid",IF(BW44>4,"ALARP",IF(BW44=0,"",IF(BW44>=1,"low"))))) | BL44: =CB44 | BO44: =CC44 | BW44: =AE44*AI44 -> 0 | BX44: =IF(BW44=0,"",IF(BW44>=1,BW44)) | BY44: =IF(BW44>11,"high",IF(BW44>6,"mid",IF(BW44>4,"ALARP",IF(BW44=0,"",IF(BW44>=1,"low"))))) | CA44: =BE44*BI44 -> 0 | CB44: =IF(CA44=0,"",IF(CA44>=1,CA44)) | CC44: =IF(CA44>11,"high",IF(CA44>6,"mid",IF(CA44>4,"ALARP",IF(CA44=0,"",IF(CA44>=1,"low"))))) | CF44: =IF(U44=0,"",IF(ISNA(U44),"",IF(E44<>"",U44,""))) | CG44: =IF(AO44=0,"",IF(ISNA(AO44),"",IF(E44<>"",AO44,""))) | CH44: =IF(AS44=0,"",IF(ISNA(AS44),"",IF(E44<>"",AS44,"")))
E45: =IF(ISNA('D4.5Why''s-D5-D6'!BY47),"",'D4.5Why''s-D5-D6'!BY47) | AL45: =BX45 | AO45: =IF(BW45>11,"high",IF(BW45>6,"mid",IF(BW45>4,"ALARP",IF(BW45=0,"",IF(BW45>=1,"low"))))) | BL45: =CB45 | BO45: =CC45 | BW45: =AE45*AI45 -> 0 | BX45: =IF(BW45=0,"",IF(BW45>=1,BW45)) | BY45: =IF(BW45>11,"high",IF(BW45>6,"mid",IF(BW45>4,"ALARP",IF(BW45=0,"",IF(BW45>=1,"low"))))) | CA45: =BE45*BI45 -> 0 | CB45: =IF(CA45=0,"",IF(CA45>=1,CA45)) | CC45: =IF(CA45>11,"high",IF(CA45>6,"mid",IF(CA45>4,"ALARP",IF(CA45=0,"",IF(CA45>=1,"low"))))) | CF45: =IF(U45=0,"",IF(ISNA(U45),"",IF(E45<>"",U45,""))) | CG45: =IF(AO45=0,"",IF(ISNA(AO45),"",IF(E45<>"",AO45,""))) | CH45: =IF(AS45=0,"",IF(ISNA(AS45),"",IF(E45<>"",AS45,"")))
E46: =IF(ISNA('D4.5Why''s-D5-D6'!BY48),"",'D4.5Why''s-D5-D6'!BY48) | AL46: =BX46 | AO46: =IF(BW46>11,"high",IF(BW46>6,"mid",IF(BW46>4,"ALARP",IF(BW46=0,"",IF(BW46>=1,"low"))))) | BL46: =CB46 | BO46: =CC46 | BW46: =AE46*AI46 -> 0 | BX46: =IF(BW46=0,"",IF(BW46>=1,BW46)) | BY46: =IF(BW46>11,"high",IF(BW46>6,"mid",IF(BW46>4,"ALARP",IF(BW46=0,"",IF(BW46>=1,"low"))))) | CA46: =BE46*BI46 -> 0 | CB46: =IF(CA46=0,"",IF(CA46>=1,CA46)) | CC46: =IF(CA46>11,"high",IF(CA46>6,"mid",IF(CA46>4,"ALARP",IF(CA46=0,"",IF(CA46>=1,"low"))))) | CF46: =IF(U46=0,"",IF(ISNA(U46),"",IF(E46<>"",U46,""))) | CG46: =IF(AO46=0,"",IF(ISNA(AO46),"",IF(E46<>"",AO46,""))) | CH46: =IF(AS46=0,"",IF(ISNA(AS46),"",IF(E46<>"",AS46,"")))
E47: =IF(ISNA('D4.5Why''s-D5-D6'!BY49),"",'D4.5Why''s-D5-D6'!BY49) | AL47: =BX47 | AO47: =IF(BW47>11,"high",IF(BW47>6,"mid",IF(BW47>4,"ALARP",IF(BW47=0,"",IF(BW47>=1,"low"))))) | BL47: =CB47 | BO47: =CC47 | BW47: =AE47*AI47 -> 0 | BX47: =IF(BW47=0,"",IF(BW47>=1,BW47)) | BY47: =IF(BW47>11,"high",IF(BW47>6,"mid",IF(BW47>4,"ALARP",IF(BW47=0,"",IF(BW47>=1,"low"))))) | CA47: =BE47*BI47 -> 0 | CB47: =IF(CA47=0,"",IF(CA47>=1,CA47)) | CC47: =IF(CA47>11,"high",IF(CA47>6,"mid",IF(CA47>4,"ALARP",IF(CA47=0,"",IF(CA47>=1,"low"))))) | CF47: =IF(U47=0,"",IF(ISNA(U47),"",IF(E47<>"",U47,""))) | CG47: =IF(AO47=0,"",IF(ISNA(AO47),"",IF(E47<>"",AO47,""))) | CH47: =IF(AS47=0,"",IF(ISNA(AS47),"",IF(E47<>"",AS47,"")))
E48: =IF(ISNA('D4.5Why''s-D5-D6'!BY50),"",'D4.5Why''s-D5-D6'!BY50) | AL48: =BX48 | AO48: =IF(BW48>11,"high",IF(BW48>6,"mid",IF(BW48>4,"ALARP",IF(BW48=0,"",IF(BW48>=1,"low"))))) | BL48: =CB48 | BO48: =CC48 | BW48: =AE48*AI48 -> 0 | BX48: =IF(BW48=0,"",IF(BW48>=1,BW48)) | BY48: =IF(BW48>11,"high",IF(BW48>6,"mid",IF(BW48>4,"ALARP",IF(BW48=0,"",IF(BW48>=1,"low"))))) | CA48: =BE48*BI48 -> 0 | CB48: =IF(CA48=0,"",IF(CA48>=1,CA48)) | CC48: =IF(CA48>11,"high",IF(CA48>6,"mid",IF(CA48>4,"ALARP",IF(CA48=0,"",IF(CA48>=1,"low"))))) | CF48: =IF(U48=0,"",IF(ISNA(U48),"",IF(E48<>"",U48,""))) | CG48: =IF(AO48=0,"",IF(ISNA(AO48),"",IF(E48<>"",AO48,""))) | CH48: =IF(AS48=0,"",IF(ISNA(AS48),"",IF(E48<>"",AS48,"")))
E49: =IF(ISNA('D4.5Why''s-D5-D6'!BY51),"",'D4.5Why''s-D5-D6'!BY51) | AL49: =BX49 | AO49: =IF(BW49>11,"high",IF(BW49>6,"mid",IF(BW49>4,"ALARP",IF(BW49=0,"",IF(BW49>=1,"low"))))) | BL49: =CB49 | BO49: =CC49 | BW49: =AE49*AI49 -> 0 | BX49: =IF(BW49=0,"",IF(BW49>=1,BW49)) | BY49: =IF(BW49>11,"high",IF(BW49>6,"mid",IF(BW49>4,"ALARP",IF(BW49=0,"",IF(BW49>=1,"low"))))) | CA49: =BE49*BI49 -> 0 | CB49: =IF(CA49=0,"",IF(CA49>=1,CA49)) | CC49: =IF(CA49>11,"high",IF(CA49>6,"mid",IF(CA49>4,"ALARP",IF(CA49=0,"",IF(CA49>=1,"low"))))) | CF49: =IF(U49=0,"",IF(ISNA(U49),"",IF(E49<>"",U49,""))) | CG49: =IF(AO49=0,"",IF(ISNA(AO49),"",IF(E49<>"",AO49,""))) | CH49: =IF(AS49=0,"",IF(ISNA(AS49),"",IF(E49<>"",AS49,"")))
E50: =IF(ISNA('D4.5Why''s-D5-D6'!BY52),"",'D4.5Why''s-D5-D6'!BY52) | AL50: =BX50 | AO50: =IF(BW50>11,"high",IF(BW50>6,"mid",IF(BW50>4,"ALARP",IF(BW50=0,"",IF(BW50>=1,"low"))))) | BL50: =CB50 | BO50: =CC50 | BW50: =AE50*AI50 -> 0 | BX50: =IF(BW50=0,"",IF(BW50>=1,BW50)) | BY50: =IF(BW50>11,"high",IF(BW50>6,"mid",IF(BW50>4,"ALARP",IF(BW50=0,"",IF(BW50>=1,"low"))))) | CA50: =BE50*BI50 -> 0 | CB50: =IF(CA50=0,"",IF(CA50>=1,CA50)) | CC50: =IF(CA50>11,"high",IF(CA50>6,"mid",IF(CA50>4,"ALARP",IF(CA50=0,"",IF(CA50>=1,"low"))))) | CF50: =IF(U50=0,"",IF(ISNA(U50),"",IF(E50<>"",U50,""))) | CG50: =IF(AO50=0,"",IF(ISNA(AO50),"",IF(E50<>"",AO50,""))) | CH50: =IF(AS50=0,"",IF(ISNA(AS50),"",IF(E50<>"",AS50,"")))
...

Sheet D4. Data-Facts-Numbers
K2: =INDIRECT('D1-D2-D3'!$J$4&"!C2")&" "&INDIRECT('D1-D2-D3'!$J$4&"!C97") -> PROBLEM SOLVING SHEET Data/Facts/Numbers | AD2: =INDIRECT('D1-D2-D3'!$J$4&"!C3") -> PSS No. | AJ2: ='D1-D2-D3'!$AI$4 -> 0 | AP2: 4.15.03.00 | AX2: =INDIRECT('D1-D2-D3'!$J$4&"!C96") -> Page 2: D4
D6: =INDIRECT('D1-D2-D3'!$J$4&"!C98") -> Rework
D7: =INDIRECT('D1-D2-D3'!$J$4&"!C102") -> Detailed information about rework
D14: =INDIRECT('D1-D2-D3'!$J$4&"!C103") -> Information about fault in QIS
D28: =INDIRECT('D1-D2-D3'!$J$4&"!C104") -> Other information
B62: =INDIRECT('D1-D2-D3'!$J$4&"!C105") -> For a comprehensible root cause analysis, draw the process flow and mark the critical process steps:

Sheet D4. Ishikawa-chart
B2: =INDIRECT('D1-D2-D3'!$J$4&"!C107") -> Guiding questions for an efficient root cause analysis
B3: =INDIRECT('D1-D2-D3'!$J$4&"!C108") -> Man | L3: =INDIRECT('D1-D2-D3'!$J$4&"!C115") -> Machine | V3: =INDIRECT('D1-D2-D3'!$J$4&"!C122") -> Material | AE3: =INDIRECT('D1-D2-D3'!$J$4&"!C128") -> Method
B4: =INDIRECT('D1-D2-D3'!$J$4&"!C109") -> Is there any risk during manipulations ? | L4: =INDIRECT('D1-D2-D3'!$J$4&"!C116") -> Are tools/machines functioning properly ? | V4: =INDIRECT('D1-D2-D3'!$J$4&"!C123") -> Are parts within defined standards ? Are standards suitable ? | AE4: =INDIRECT('D1-D2-D3'!$J$4&"!C129") -> Are work instructions posted at workstations ?
B5: =INDIRECT('D1-D2-D3'!$J$4&"!C110") -> Are workers abilited to the job ? (check concerned prod.period) | L5: =INDIRECT('D1-D2-D3'!$J$4&"!C117") -> Has preventive maintenance been performed ? | V5: =INDIRECT('D1-D2-D3'!$J$4&"!C124") -> Are used components/materials within specifications ? | AE5: =INDIRECT('D1-D2-D3'!$J$4&"!C130") -> Are work instructions updated ?
B6: =INDIRECT('D1-D2-D3'!$J$4&"!C111") -> Did workers received necessary training ? | L6: =INDIRECT('D1-D2-D3'!$J$4&"!C118") -> Did any specific event occure ? (Power shutdown,…) | V6: =INDIRECT('D1-D2-D3'!$J$4&"!C125") -> Were there any changes/modifications on components/materials ? | AE6: =INDIRECT('D1-D2-D3'!$J$4&"!C131") -> Have correct tools/fixtures been used ?
B7: =INDIRECT('D1-D2-D3'!$J$4&"!C112") -> Is training adapted to the needs ? | L7: =INDIRECT('D1-D2-D3'!$J$4&"!C119") -> Do error proofing systems work properly ? (Poka yoke, Control station,…) | V7: =INDIRECT('D1-D2-D3'!$J$4&"!C126") -> Are all components/materials approved ? | AE7: =INDIRECT('D1-D2-D3'!$J$4&"!C132") -> Is the job done the same way in all shifts ?
B8: =INDIRECT('D1-D2-D3'!$J$4&"!C113") -> Do workers perfectly understand applicable work instructions ? | L8: =INDIRECT('D1-D2-D3'!$J$4&"!C120") -> Have machine/process parameters been properly set up ? | V8: =INDIRECT('D1-D2-D3'!$J$4&"!C127") -> Are correct components/materials used ? | AE8: =INDIRECT('D1-D2-D3'!$J$4&"!C133") -> Is preventive maintenance defined ? Is it sufficient ?
B9: =INDIRECT('D1-D2-D3'!$J$4&"!C114") -> Were all work instructions properly followed and applied ? | L9: =INDIRECT('D1-D2-D3'!$J$4&"!C121") -> Are machine/process parameters properly defined ?
I12: =INDIRECT('D1-D2-D3'!$J$4&"!C2")&" "&INDIRECT('D1-D2-D3'!$J$4&"!C136") -> PROBLEM SOLVING SHEET Ishikawa-Chart | W12: =INDIRECT('D1-D2-D3'!$J$4&"!C3") -> PSS No. | Y12: ='D1-D2-D3'!$AI$4 -> 0 | AB12: 4.15.03.00 | AF12: =INDIRECT('D1-D2-D3'!$J$4&"!C106") -> Page 3: D4
C14: =INDIRECT('D1-D2-D3'!$J$4&"!C136") -> Ishikawa-Chart
F16: =INDIRECT('D1-D2-D3'!$J$4&"!C139") -> Occurrence | W16: =INDIRECT('D1-D2-D3'!$J$4&"!C140") -> Non-detection | AS16: YES - Occurence | AY16: YES - Non det | BG16: CAUSE FOR D4. 5WHYs - together
F18: =INDIRECT('D1-D2-D3'!$J$4&"!C108") -> Man | L18: =INDIRECT('D1-D2-D3'!$J$4&"!C115") -> Machine | R18: =INDIRECT('D1-D2-D3'!$J$4&"!C122") -> Material | X18: =INDIRECT('D1-D2-D3'!$J$4&"!C108") -> Man | AD18: =INDIRECT('D1-D2-D3'!$J$4&"!C115") -> Machine | AJ18: =INDIRECT('D1-D2-D3'!$J$4&"!C122") -> Material | AS18: 0 | AZ18: 0 | BG18: 0
AR19: 1 | AS19: =IF($AT19<>"",AS18+1,"") | AT19: =IF($J19=DropDown!$N$11,F19,"") | AV19: 1 | AW19: =VLOOKUP($AV19,$AS$19:$AT$48,2,FALSE) -> #N/A | AX19: =IF(ISNA(AW19),"",AW19) | AY19: 1 | AZ19: =IF($BA19<>"",AZ18+1,"") | BA19: =IF($AB19=DropDown!$N$11,X19,"") | BC19: 1 | BD19: =VLOOKUP($BC19,$AZ$19:$BA$48,2,FALSE) -> #N/A | BE19: =IF(ISNA(BD19),"",BD19) | BG19: =IF($BH19<>"",BG18+1,"") | BH19: =IF(AX19="","",AX19) | BI19: 1 | BJ19: =VLOOKUP($BI19,$BG$19:$BH$48,2,FALSE) -> #N/A | BK19: =IF(ISNA(BJ19),"",BJ19)
AS20: =IF($AT20<>"",MAX(AS$18:AS19)+1,"") | AT20: =IF($J20=DropDown!$N$11,F20,"") | AV20: 2 | AW20: =VLOOKUP($AV20,$AS$19:$AT$48,2,FALSE) -> #N/A | AX20: =IF(ISNA(AW20),"",AW20) | AZ20: =IF($BA20<>"",MAX(AZ$18:AZ19)+1,"") | BA20: =IF($AB20=DropDown!$N$11,X20,"") | BC20: 2 | BD20: =VLOOKUP($BC20,$AZ$19:$BA$48,2,FALSE) -> #N/A | BE20: =IF(ISNA(BD20),"",BD20) | BG20: =IF($BH20<>"",MAX(BG$18:BG19)+1,"") | BH20: =IF(AX20="","",AX20) | BI20: 2 | BJ20: =VLOOKUP($BI20,$BG$19:$BH$48,2,FALSE) -> #N/A | BK20: =IF(ISNA(BJ20),"",BJ20)
AS21: =IF($AT21<>"",MAX(AS$18:AS20)+1,"") | AT21: =IF($J21=DropDown!$N$11,F21,"") | AV21: 3 | AW21: =VLOOKUP($AV21,$AS$19:$AT$48,2,FALSE) -> #N/A | AX21: =IF(ISNA(AW21),"",AW21) | AZ21: =IF($BA21<>"",MAX(AZ$18:AZ20)+1,"") | BA21: =IF($AB21=DropDown!$N$11,X21,"") | BC21: 3 | BD21: =VLOOKUP($BC21,$AZ$19:$BA$48,2,FALSE) -> #N/A | BE21: =IF(ISNA(BD21),"",BD21) | BG21: =IF($BH21<>"",MAX(BG$18:BG20)+1,"") | BH21: =IF(AX21="","",AX21) | BI21: 3 | BJ21: =VLOOKUP($BI21,$BG$19:$BH$48,2,FALSE) -> #N/A | BK21: =IF(ISNA(BJ21),"",BJ21)
AS22: =IF($AT22<>"",MAX(AS$18:AS21)+1,"") | AT22: =IF($J22=DropDown!$N$11,F22,"") | AV22: 4 | AW22: =VLOOKUP($AV22,$AS$19:$AT$48,2,FALSE) -> #N/A | AX22: =IF(ISNA(AW22),"",AW22) | AZ22: =IF($BA22<>"",MAX(AZ$18:AZ21)+1,"") | BA22: =IF($AB22=DropDown!$N$11,X22,"") | BC22: 4 | BD22: =VLOOKUP($BC22,$AZ$19:$BA$48,2,FALSE) -> #N/A | BE22: =IF(ISNA(BD22),"",BD22) | BG22: =IF($BH22<>"",MAX(BG$18:BG21)+1,"") | BH22: =IF(AX22="","",AX22) | BI22: 4 | BJ22: =VLOOKUP($BI22,$BG$19:$BH$48,2,FALSE) -> #N/A | BK22: =IF(ISNA(BJ22),"",BJ22)
AS23: =IF($AT23<>"",MAX(AS$18:AS22)+1,"") | AT23: =IF($J23=DropDown!$N$11,F23,"") | AV23: 5 | AW23: =VLOOKUP($AV23,$AS$19:$AT$48,2,FALSE) -> #N/A | AX23: =IF(ISNA(AW23),"",AW23) | AZ23: =IF($BA23<>"",MAX(AZ$18:AZ22)+1,"") | BA23: =IF($AB23=DropDown!$N$11,X23,"") | BC23: 5 | BD23: =VLOOKUP($BC23,$AZ$19:$BA$48,2,FALSE) -> #N/A | BE23: =IF(ISNA(BD23),"",BD23) | BG23: =IF($BH23<>"",MAX(BG$18:BG22)+1,"") | BH23: =IF(AX23="","",AX23) | BI23: 5 | BJ23: =VLOOKUP($BI23,$BG$19:$BH$48,2,FALSE) -> #N/A | BK23: =IF(ISNA(BJ23),"",BJ23)
AR24: 2 | AS24: =IF($AT24<>"",MAX(AS$18:AS23)+1,"") | AT24: =IF($P19=DropDown!$N$11,L19,"") | AV24: 6 | AW24: =VLOOKUP($AV24,$AS$19:$AT$48,2,FALSE) -> #N/A | AX24: =IF(ISNA(AW24),"",AW24) | AY24: 2 | AZ24: =IF($BA24<>"",MAX(AZ$18:AZ23)+1,"") | BA24: =IF($AH19=DropDown!$N$11,AD19,"") | BC24: 6 | BD24: =VLOOKUP($BC24,$AZ$19:$BA$48,2,FALSE) -> #N/A | BE24: =IF(ISNA(BD24),"",BD24) | BG24: =IF($BH24<>"",MAX(BG$18:BG23)+1,"") | BH24: =IF(AX24="","",AX24) | BI24: 6 | BJ24: =VLOOKUP($BI24,$BG$19:$BH$48,2,FALSE) -> #N/A | BK24: =IF(ISNA(BJ24),"",BJ24)
AS25: =IF($AT25<>"",MAX(AS$18:AS24)+1,"") | AT25: =IF($P20=DropDown!$N$11,L20,"") | AV25: 7 | AW25: =VLOOKUP($AV25,$AS$19:$AT$48,2,FALSE) -> #N/A | AX25: =IF(ISNA(AW25),"",AW25) | AZ25: =IF($BA25<>"",MAX(AZ$18:AZ24)+1,"") | BA25: =IF($AH20=DropDown!$N$11,AD20,"") | BC25: 7 | BD25: =VLOOKUP($BC25,$AZ$19:$BA$48,2,FALSE) -> #N/A | BE25: =IF(ISNA(BD25),"",BD25) | BG25: =IF($BH25<>"",MAX(BG$18:BG24)+1,"") | BH25: =IF(AX25="","",AX25) | BI25: 7 | BJ25: =VLOOKUP($BI25,$BG$19:$BH$48,2,FALSE) -> #N/A | BK25: =IF(ISNA(BJ25),"",BJ25)
AS26: =IF($AT26<>"",MAX(AS$18:AS25)+1,"") | AT26: =IF($P21=DropDown!$N$11,L21,"") | AV26: 8 | AW26: =VLOOKUP($AV26,$AS$19:$AT$48,2,FALSE) -> #N/A | AX26: =IF(ISNA(AW26),"",AW26) | AZ26: =IF($BA26<>"",MAX(AZ$18:AZ25)+1,"") | BA26: =IF($AH21=DropDown!$N$11,AD21,"") | BC26: 8 | BD26: =VLOOKUP($BC26,$AZ$19:$BA$48,2,FALSE) -> #N/A | BE26: =IF(ISNA(BD26),"",BD26) | BG26: =IF($BH26<>"",MAX(BG$18:BG25)+1,"") | BH26: =IF(AX26="","",AX26) | BI26: 8 | BJ26: =VLOOKUP($BI26,$BG$19:$BH$48,2,FALSE) -> #N/A | BK26: =IF(ISNA(BJ26),"",BJ26)
AS27: =IF($AT27<>"",MAX(AS$18:AS26)+1,"") | AT27: =IF($P22=DropDown!$N$11,L22,"") | AV27: 9 | AW27: =VLOOKUP($AV27,$AS$19:$AT$48,2,FALSE) -> #N/A | AX27: =IF(ISNA(AW27),"",AW27) | AZ27: =IF($BA27<>"",MAX(AZ$18:AZ26)+1,"") | BA27: =IF($AH22=DropDown!$N$11,AD22,"") | BC27: 9 | BD27: =VLOOKUP($BC27,$AZ$19:$BA$48,2,FALSE) -> #N/A | BE27: =IF(ISNA(BD27),"",BD27) | BG27: =IF($BH27<>"",MAX(BG$18:BG26)+1,"") | BH27: =IF(AX27="","",AX27) | BI27: 9 | BJ27: =VLOOKUP($BI27,$BG$19:$BH$48,2,FALSE) -> #N/A | BK27: =IF(ISNA(BJ27),"",BJ27)
AS28: =IF($AT28<>"",MAX(AS$18:AS27)+1,"") | AT28: =IF($P23=DropDown!$N$11,L23,"") | AV28: 10 | AW28: =VLOOKUP($AV28,$AS$19:$AT$48,2,FALSE) -> #N/A | AX28: =IF(ISNA(AW28),"",AW28) | AZ28: =IF($BA28<>"",MAX(AZ$18:AZ27)+1,"") | BA28: =IF($AH23=DropDown!$N$11,AD23,"") | BC28: 10 | BD28: =VLOOKUP($BC28,$AZ$19:$BA$48,2,FALSE) -> #N/A | BE28: =IF(ISNA(BD28),"",BD28) | BG28: =IF($BH28<>"",MAX(BG$18:BG27)+1,"") | BH28: =IF(AX28="","",AX28) | BI28: 10 | BJ28: =VLOOKUP($BI28,$BG$19:$BH$48,2,FALSE) -> #N/A | BK28: =IF(ISNA(BJ28),"",BJ28)
AR29: 3 | AS29: =IF($AT29<>"",MAX(AS$18:AS28)+1,"") | AT29: =IF($U19=DropDown!$N$11,R19,"") | AV29: 11 | AW29: =VLOOKUP($AV29,$AS$19:$AT$48,2,FALSE) -> #N/A | AX29: =IF(ISNA(AW29),"",AW29) | AY29: 3 | AZ29: =IF($BA29<>"",MAX(AZ$18:AZ28)+1,"") | BA29: =IF($AM19=DropDown!$N$11,AJ19,"") | BC29: 11 | BD29: =VLOOKUP($BC29,$AZ$19:$BA$48,2,FALSE) -> #N/A | BE29: =IF(ISNA(BD29),"",BD29) | BG29: =IF($BH29<>"",MAX(BG$18:BG28)+1,"") | BH29: =IF(AX29="","",AX29) | BI29: 11 | BJ29: =VLOOKUP($BI29,$BG$19:$BH$48,2,FALSE) -> #N/A | BK29: =IF(ISNA(BJ29),"",BJ29)
AS30: =IF($AT30<>"",MAX(AS$18:AS29)+1,"") | AT30: =IF($U20=DropDown!$N$11,R20,"") | AV30: 12 | AW30: =VLOOKUP($AV30,$AS$19:$AT$48,2,FALSE) -> #N/A | AX30: =IF(ISNA(AW30),"",AW30) | AZ30: =IF($BA30<>"",MAX(AZ$18:AZ29)+1,"") | BA30: =IF($AM20=DropDown!$N$11,AJ20,"") | BC30: 12 | BD30: =VLOOKUP($BC30,$AZ$19:$BA$48,2,FALSE) -> #N/A | BE30: =IF(ISNA(BD30),"",BD30) | BG30: =IF($BH30<>"",MAX(BG$18:BG29)+1,"") | BH30: =IF(AX30="","",AX30) | BI30: 12 | BJ30: =VLOOKUP($BI30,$BG$19:$BH$48,2,FALSE) -> #N/A | BK30: =IF(ISNA(BJ30),"",BJ30)
AS31: =IF($AT31<>"",MAX(AS$18:AS30)+1,"") | AT31: =IF($U21=DropDown!$N$11,R21,"") | AV31: 13 | AW31: =VLOOKUP($AV31,$AS$19:$AT$48,2,FALSE) -> #N/A | AX31: =IF(ISNA(AW31),"",AW31) | AZ31: =IF($BA31<>"",MAX(AZ$18:AZ30)+1,"") | BA31: =IF($AM21=DropDown!$N$11,AJ21,"") | BC31: 13 | BD31: =VLOOKUP($BC31,$AZ$19:$BA$48,2,FALSE) -> #N/A | BE31: =IF(ISNA(BD31),"",BD31) | BG31: =IF($BH31<>"",MAX(BG$18:BG30)+1,"") | BH31: =IF(AX31="","",AX31) | BI31: 13 | BJ31: =VLOOKUP($BI31,$BG$19:$BH$48,2,FALSE) -> #N/A | BK31: =IF(ISNA(BJ31),"",BJ31)
F32: =INDIRECT('D1-D2-D3'!$J$4&"!C128") -> Method | L32: =INDIRECT('D1-D2-D3'!$J$4&"!C134") -> Environment | R32: Others | X32: =INDIRECT('D1-D2-D3'!$J$4&"!C128") -> Method | AB32: =INDIRECT('D1-D2-D3'!$J$4&"!C128") -> Method | AD32: =INDIRECT('D1-D2-D3'!$J$4&"!C134") -> Environment | AH32: =INDIRECT('D1-D2-D3'!$J$4&"!C134") -> Environment | AJ32: Others | AM32: Others | AS32: =IF($AT32<>"",MAX(AS$18:AS31)+1,"") | AT32: =IF($U22=DropDown!$N$11,R22,"") | AV32: 14 | AW32: =VLOOKUP($AV32,$AS$19:$AT$48,2,FALSE) -> #N/A | AX32: =IF(ISNA(AW32),"",AW32) | AZ32: =IF($BA32<>"",MAX(AZ$18:AZ31)+1,"") | BA32: =IF($AM22=DropDown!$N$11,AJ22,"") | BC32: 14 | BD32: =VLOOKUP($BC32,$AZ$19:$BA$48,2,FALSE) -> #N/A | BE32: =IF(ISNA(BD32),"",BD32) | BG32: =IF($BH32<>"",MAX(BG$18:BG31)+1,"") | BH32: =IF(AX32="","",AX32) | BI32: 14 | BJ32: =VLOOKUP($BI32,$BG$19:$BH$48,2,FALSE) -> #N/A | BK32: =IF(ISNA(BJ32),"",BJ32)
AS33: =IF($AT33<>"",MAX(AS$18:AS32)+1,"") | AT33: =IF($U23=DropDown!$N$11,R23,"") | AV33: 15 | AW33: =VLOOKUP($AV33,$AS$19:$AT$48,2,FALSE) -> #N/A | AX33: =IF(ISNA(AW33),"",AW33) | AZ33: =IF($BA33<>"",MAX(AZ$18:AZ32)+1,"") | BA33: =IF($AM23=DropDown!$N$11,AJ23,"") | BC33: 15 | BD33: =VLOOKUP($BC33,$AZ$19:$BA$48,2,FALSE) -> #N/A | BE33: =IF(ISNA(BD33),"",BD33) | BG33: =IF($BH33<>"",MAX(BG$18:BG32)+1,"") | BH33: =IF(BE19="","",BE19) | BI33: 15 | BJ33: =VLOOKUP($BI33,$BG$19:$BH$48,2,FALSE) -> #N/A | BK33: =IF(ISNA(BJ33),"",BJ33)
AR34: 4 | AS34: =IF($AT34<>"",MAX(AS$18:AS33)+1,"") | AT34: =IF($J33=DropDown!$N$11,F33,"") | AV34: 16 | AW34: =VLOOKUP($AV34,$AS$19:$AT$48,2,FALSE) -> #N/A | AX34: =IF(ISNA(AW34),"",AW34) | AY34: 4 | AZ34: =IF($BA34<>"",MAX(AZ$18:AZ33)+1,"") | BA34: =IF($AB33=DropDown!$N$11,X33,"") | BC34: 16 | BD34: =VLOOKUP($BC34,$AZ$19:$BA$48,2,FALSE) -> #N/A | BE34: =IF(ISNA(BD34),"",BD34) | BG34: =IF($BH34<>"",MAX(BG$18:BG33)+1,"") | BH34: =IF(BE20="","",BE20) | BI34: 16 | BJ34: =VLOOKUP($BI34,$BG$19:$BH$48,2,FALSE) -> #N/A | BK34: =IF(ISNA(BJ34),"",BJ34)
AS35: =IF($AT35<>"",MAX(AS$18:AS34)+1,"") | AT35: =IF($J34=DropDown!$N$11,F34,"") | AV35: 17 | AW35: =VLOOKUP($AV35,$AS$19:$AT$48,2,FALSE) -> #N/A | AX35: =IF(ISNA(AW35),"",AW35) | AZ35: =IF($BA35<>"",MAX(AZ$18:AZ34)+1,"") | BA35: =IF($AB34=DropDown!$N$11,X34,"") | BC35: 17 | BD35: =VLOOKUP($BC35,$AZ$19:$BA$48,2,FALSE) -> #N/A | BE35: =IF(ISNA(BD35),"",BD35) | BG35: =IF($BH35<>"",MAX(BG$18:BG34)+1,"") | BH35: =IF(BE21="","",BE21) | BI35: 17 | BJ35: =VLOOKUP($BI35,$BG$19:$BH$48,2,FALSE) -> #N/A | BK35: =IF(ISNA(BJ35),"",BJ35)
AS36: =IF($AT36<>"",MAX(AS$18:AS35)+1,"") | AT36: =IF($J35=DropDown!$N$11,F35,"") | AV36: 18 | AW36: =VLOOKUP($AV36,$AS$19:$AT$48,2,FALSE) -> #N/A | AX36: =IF(ISNA(AW36),"",AW36) | AZ36: =IF($BA36<>"",MAX(AZ$18:AZ35)+1,"") | BA36: =IF($AB35=DropDown!$N$11,X35,"") | BC36: 18 | BD36: =VLOOKUP($BC36,$AZ$19:$BA$48,2,FALSE) -> #N/A | BE36: =IF(ISNA(BD36),"",BD36) | BG36: =IF($BH36<>"",MAX(BG$18:BG35)+1,"") | BH36: =IF(BE22="","",BE22) | BI36: 18 | BJ36: =VLOOKUP($BI36,$BG$19:$BH$48,2,FALSE) -> #N/A | BK36: =IF(ISNA(BJ36),"",BJ36)
AS37: =IF($AT37<>"",MAX(AS$18:AS36)+1,"") | AT37: =IF($J36=DropDown!$N$11,F36,"") | AV37: 19 | AW37: =VLOOKUP($AV37,$AS$19:$AT$48,2,FALSE) -> #N/A | AX37: =IF(ISNA(AW37),"",AW37) | AZ37: =IF($BA37<>"",MAX(AZ$18:AZ36)+1,"") | BA37: =IF($AB36=DropDown!$N$11,X36,"") | BC37: 19 | BD37: =VLOOKUP($BC37,$AZ$19:$BA$48,2,FALSE) -> #N/A | BE37: =IF(ISNA(BD37),"",BD37) | BG37: =IF($BH37<>"",MAX(BG$18:BG36)+1,"") | BH37: =IF(BE23="","",BE23) | BI37: 19 | BJ37: =VLOOKUP($BI37,$BG$19:$BH$48,2,FALSE) -> #N/A | BK37: =IF(ISNA(BJ37),"",BJ37)
AS38: =IF($AT38<>"",MAX(AS$18:AS37)+1,"") | AT38: =IF($J37=DropDown!$N$11,F37,"") | AV38: 20 | AW38: =VLOOKUP($AV38,$AS$19:$AT$48,2,FALSE) -> #N/A | AX38: =IF(ISNA(AW38),"",AW38) | AZ38: =IF($BA38<>"",MAX(AZ$18:AZ37)+1,"") | BA38: =IF($AB37=DropDown!$N$11,X37,"") | BC38: 20 | BD38: =VLOOKUP($BC38,$AZ$19:$BA$48,2,FALSE) -> #N/A | BE38: =IF(ISNA(BD38),"",BD38) | BG38: =IF($BH38<>"",MAX(BG$18:BG37)+1,"") | BH38: =IF(BE24="","",BE24) | BI38: 20 | BJ38: =VLOOKUP($BI38,$BG$19:$BH$48,2,FALSE) -> #N/A | BK38: =IF(ISNA(BJ38),"",BJ38)
AR39: 5 | AS39: =IF($AT39<>"",MAX(AS$18:AS38)+1,"") | AT39: =IF($P33=DropDown!$N$11,L33,"") | AV39: 21 | AW39: =VLOOKUP($AV39,$AS$19:$AT$48,2,FALSE) -> #N/A | AX39: =IF(ISNA(AW39),"",AW39) | AY39: 5 | AZ39: =IF($BA39<>"",MAX(AZ$18:AZ38)+1,"") | BA39: =IF($AH33=DropDown!$N$11,AD33,"") | BC39: 21 | BD39: =VLOOKUP($BC39,$AZ$19:$BA$48,2,FALSE) -> #N/A | BE39: =IF(ISNA(BD39),"",BD39) | BG39: =IF($BH39<>"",MAX(BG$18:BG38)+1,"") | BH39: =IF(BE25="","",BE25) | BI39: 21 | BJ39: =VLOOKUP($BI39,$BG$19:$BH$48,2,FALSE) -> #N/A | BK39: =IF(ISNA(BJ39),"",BJ39)
AS40: =IF($AT40<>"",MAX(AS$18:AS39)+1,"") | AT40: =IF($P34=DropDown!$N$11,L34,"") | AV40: 22 | AW40: =VLOOKUP($AV40,$AS$19:$AT$48,2,FALSE) -> #N/A | AX40: =IF(ISNA(AW40),"",AW40) | AZ40: =IF($BA40<>"",MAX(AZ$18:AZ39)+1,"") | BA40: =IF($AH34=DropDown!$N$11,AD34,"") | BC40: 22 | BD40: =VLOOKUP($BC40,$AZ$19:$BA$48,2,FALSE) -> #N/A | BE40: =IF(ISNA(BD40),"",BD40) | BG40: =IF($BH40<>"",MAX(BG$18:BG39)+1,"") | BH40: =IF(BE26="","",BE26) | BI40: 22 | BJ40: =VLOOKUP($BI40,$BG$19:$BH$48,2,FALSE) -> #N/A | BK40: =IF(ISNA(BJ40),"",BJ40)
AS41: =IF($AT41<>"",MAX(AS$18:AS40)+1,"") | AT41: =IF($P35=DropDown!$N$11,L35,"") | AV41: 23 | AW41: =VLOOKUP($AV41,$AS$19:$AT$48,2,FALSE) -> #N/A | AX41: =IF(ISNA(AW41),"",AW41) | AZ41: =IF($BA41<>"",MAX(AZ$18:AZ40)+1,"") | BA41: =IF($AH35=DropDown!$N$11,AD35,"") | BC41: 23 | BD41: =VLOOKUP($BC41,$AZ$19:$BA$48,2,FALSE) -> #N/A | BE41: =IF(ISNA(BD41),"",BD41) | BG41: =IF($BH41<>"",MAX(BG$18:BG40)+1,"") | BH41: =IF(BE27="","",BE27) | BI41: 23 | BJ41: =VLOOKUP($BI41,$BG$19:$BH$48,2,FALSE) -> #N/A | BK41: =IF(ISNA(BJ41),"",BJ41)
AS42: =IF($AT42<>"",MAX(AS$18:AS41)+1,"") | AT42: =IF($P36=DropDown!$N$11,L36,"") | AV42: 24 | AW42: =VLOOKUP($AV42,$AS$19:$AT$48,2,FALSE) -> #N/A | AX42: =IF(ISNA(AW42),"",AW42) | AZ42: =IF($BA42<>"",MAX(AZ$18:AZ41)+1,"") | BA42: =IF($AH36=DropDown!$N$11,AD36,"") | BC42: 24 | BD42: =VLOOKUP($BC42,$AZ$19:$BA$48,2,FALSE) -> #N/A | BE42: =IF(ISNA(BD42),"",BD42) | BG42: =IF($BH42<>"",MAX(BG$18:BG41)+1,"") | BH42: =IF(BE28="","",BE28) | BI42: 24 | BJ42: =VLOOKUP($BI42,$BG$19:$BH$48,2,FALSE) -> #N/A | BK42: =IF(ISNA(BJ42),"",BJ42)
AS43: =IF($AT43<>"",MAX(AS$18:AS42)+1,"") | AT43: =IF($P37=DropDown!$N$11,L37,"") | AV43: 25 | AW43: =VLOOKUP($AV43,$AS$19:$AT$48,2,FALSE) -> #N/A | AX43: =IF(ISNA(AW43),"",AW43) | AZ43: =IF($BA43<>"",MAX(AZ$18:AZ42)+1,"") | BA43: =IF($AH37=DropDown!$N$11,AD37,"") | BC43: 25 | BD43: =VLOOKUP($BC43,$AZ$19:$BA$48,2,FALSE) -> #N/A | BE43: =IF(ISNA(BD43),"",BD43) | BG43: =IF($BH43<>"",MAX(BG$18:BG42)+1,"") | BH43: =IF(BE29="","",BE29) | BI43: 25 | BJ43: =VLOOKUP($BI43,$BG$19:$BH$48,2,FALSE) -> #N/A | BK43: =IF(ISNA(BJ43),"",BJ43)
J44: =INDIRECT('D1-D2-D3'!$J$4&"!C142") -> Why the cause can be excluded (is not a real root cause) ? | AR44: 6 | AS44: =IF($AT44<>"",MAX(AS$18:AS43)+1,"") | AT44: =IF($U33=DropDown!$N$11,R33,"") | AV44: 26 | AW44: =VLOOKUP($AV44,$AS$19:$AT$48,2,FALSE) -> #N/A | AX44: =IF(ISNA(AW44),"",AW44) | AY44: 6 | AZ44: =IF($BA44<>"",MAX(AZ$18:AZ43)+1,"") | BA44: =IF($AM33=DropDown!$N$11,AJ33,"") | BC44: 26 | BD44: =VLOOKUP($BC44,$AZ$19:$BA$48,2,FALSE) -> #N/A | BE44: =IF(ISNA(BD44),"",BD44) | BG44: =IF($BH44<>"",MAX(BG$18:BG43)+1,"") | BH44: =IF(BE30="","",BE30) | BI44: 26 | BJ44: =VLOOKUP($BI44,$BG$19:$BH$48,2,FALSE) -> #N/A | BK44: =IF(ISNA(BJ44),"",BJ44)
AS45: =IF($AT45<>"",MAX(AS$18:AS44)+1,"") | AT45: =IF($U34=DropDown!$N$11,R34,"") | AV45: 27 | AW45: =VLOOKUP($AV45,$AS$19:$AT$48,2,FALSE) -> #N/A | AX45: =IF(ISNA(AW45),"",AW45) | AZ45: =IF($BA45<>"",MAX(AZ$18:AZ44)+1,"") | BA45: =IF($AM34=DropDown!$N$11,AJ34,"") | BC45: 27 | BD45: =VLOOKUP($BC45,$AZ$19:$BA$48,2,FALSE) -> #N/A | BE45: =IF(ISNA(BD45),"",BD45) | BG45: =IF($BH45<>"",MAX(BG$18:BG44)+1,"") | BH45: =IF(BE31="","",BE31) | BI45: 27 | BJ45: =VLOOKUP($BI45,$BG$19:$BH$48,2,FALSE) -> #N/A | BK45: =IF(ISNA(BJ45),"",BJ45)
F46: =INDIRECT('D1-D2-D3'!$J$4&"!C139") -> Occurrence | X46: =INDIRECT('D1-D2-D3'!$J$4&"!C140") -> Non-detection | AS46: =IF($AT46<>"",MAX(AS$18:AS45)+1,"") | AT46: =IF($U35=DropDown!$N$11,R35,"") | AV46: 28 | AW46: =VLOOKUP($AV46,$AS$19:$AT$48,2,FALSE) -> #N/A | AX46: =IF(ISNA(AW46),"",AW46) | AZ46: =IF($BA46<>"",MAX(AZ$18:AZ45)+1,"") | BA46: =IF($AM35=DropDown!$N$11,AJ35,"") | BC46: 28 | BD46: =VLOOKUP($BC46,$AZ$19:$BA$48,2,FALSE) -> #N/A | BE46: =IF(ISNA(BD46),"",BD46) | BG46: =IF($BH46<>"",MAX(BG$18:BG45)+1,"") | BH46: =IF(BE32="","",BE32) | BI46: 28 | BJ46: =VLOOKUP($BI46,$BG$19:$BH$48,2,FALSE) -> #N/A | BK46: =IF(ISNA(BJ46),"",BJ46)
...

Sheet D4.5Why's-D5-D6
M1: =INDIRECT('D1-D2-D3'!$J$4&"!C224") -> AP-team leader
I3: =INDIRECT('D1-D2-D3'!$J$4&"!C2")&" "&INDIRECT('D1-D2-D3'!$J$4&"!C145") -> PROBLEM SOLVING SHEET D4 - Root cause analysis | T3: =INDIRECT('D1-D2-D3'!$J$4&"!C3") -> PSS No. | V3: ='D1-D2-D3'!AI4 -> 0 | Y3: 4.15.03.00 | AE3: =INDIRECT('D1-D2-D3'!$J$4&"!C143") -> Page 4: D4-D5-D6
B6: =INDIRECT('D1-D2-D3'!$J$4&"!C145") -> D4 - Root cause analysis | K6: =INDIRECT('D1-D2-D3'!$J$4&"!C68") -> Status | P6: =INDIRECT('D1-D2-D3'!$J$4&"!C69") -> Date | AB6: =INDIRECT('D1-D2-D3'!$J$4&"!C161") -> D5 - Corrective Action(s) | AF6: =INDIRECT('D1-D2-D3'!$J$4&"!C162") -> D6 - Implementation of permanent corrective action(s)
AB9: =INDIRECT('D1-D2-D3'!$J$4&"!C146") -> Were the relevant emloyees trained ? | AI9: =INDIRECT('D1-D2-D3'!$J$4&"!C147") -> Date of training
AB11: =INDIRECT('D1-D2-D3'!$J$4&"!C93") -> Comments | AG11: =INDIRECT('D1-D2-D3'!$J$4&"!C83") -> Responsible
AG13: =INDIRECT('D1-D2-D3'!$J$4&"!C148") -> Date of effectiveness check of training
D16: ='D1-D2-D3'!D48&":" -> Problem description: | J16: =INDIRECT('D1-D2-D3'!$J$4&"!C150") -> 5-Why-Analysis | X16: =INDIRECT('D1-D2-D3'!$J$4&"!C157") -> Fault category | Z16: =INDIRECT('D1-D2-D3'!$J$4&"!C158") -> Verification of the causes | AB16: =INDIRECT('D1-D2-D3'!$J$4&"!C163") -> Action Plan
D17: =IF('D1-D2-D3'!V48="","",'D1-D2-D3'!V48) | J17: =INDIRECT('D1-D2-D3'!$J$4&"!C137") -> Technical consideration | AM17: TECNICAL - ROOT CAUSE AND 5WHYs | AX17: FINAL 5WHYs for 8D | BH17: ACTION PLAN - TECHN: OCC+cause | BP17: ACTION PLAN - TECH: CAUSE + ACTION if Action is available | BW17: FINAL Cause + Corr.actions for 8D | CH17: 5WHY for SYSTEM
D18: =INDIRECT('D1-D2-D3'!$J$4&"!C149") -> Factors identification | I18: =INDIRECT('D1-D2-D3'!$J$4&"!C151") -> Influent factors | J18: =INDIRECT('D1-D2-D3'!$J$4&"!C152") -> Why 1 | L18: =INDIRECT('D1-D2-D3'!$J$4&"!C153") -> Why 2 | O18: =INDIRECT('D1-D2-D3'!$J$4&"!C154") -> Why 3 | Q18: =INDIRECT('D1-D2-D3'!$J$4&"!C155") -> Why 4 | T18: =INDIRECT('D1-D2-D3'!$J$4&"!C156") -> Why 5 | X18: =INDIRECT('D1-D2-D3'!$J$4&"!C159") -> Category | Z18: =INDIRECT('D1-D2-D3'!$J$4&"!C160") -> Method of cause verification | AB18: =INDIRECT('D1-D2-D3'!$J$4&"!C164") -> Corrective Action | AE18: =INDIRECT('D1-D2-D3'!$J$4&"!C165") -> Pic. No. | AF18: =INDIRECT('D1-D2-D3'!$J$4&"!C83") -> Responsible | AH18: =INDIRECT('D1-D2-D3'!$J$4&"!C166") -> Target Date | AJ18: =INDIRECT('D1-D2-D3'!$J$4&"!C84") -> Impl. Date | AM18: 0 | AP18: 1 | AQ18: 2 | AR18: 3 | AS18: 4 | AT18: 5 | AX18: SVERWEIS - 5 Whys | BH18: 0 | BI18: occ | BJ18: fault | BK18: action | BL18: respo | BM18: target | BN18: implem | BO18: 0 | BW18: SVERWEIS | BY18: Act | BZ18: respons | CA18: Target | CB18: impl
D19: =INDIRECT('D1-D2-D3'!$J$4&"!C149")&"/"& INDIRECT('D1-D2-D3'!$J$4&"!C151") -> Factors identification/Influent factors | AM19: =IF($AN19<>"",AM18+1,"") | AN19: =IF(AP19=0,"",IF(ISNA(AP19),"",IF($I19<>"",G19,""))) | AO19: =IF(AP19=0,"",IF(ISNA(AP19),"",IF($I19<>"",I19,""))) | AP19: =IF($I19<>"",J19,"") | AQ19: =IF($I19<>"",L19,"") | AR19: =IF($I19<>"",O19,"") | AS19: =IF($I19<>"",Q19,"") | AT19: =IF($I19<>"",T19,"") | AU19: =IF($I19<>"",X19,"") | AV19: =IF($I19<>"",Z19,"") | AW19: 1 | AX19: =VLOOKUP($AW19,$AM$19:$AV$28,2,FALSE) -> #N/A | AY19: =VLOOKUP($AW19,$AM$19:$AV$28,3,FALSE) -> #N/A | AZ19: =VLOOKUP($AW19,$AM$19:$AV$28,4,FALSE) -> #N/A | BA19: =VLOOKUP($AW19,$AM$19:$AV$28,5,FALSE) -> #N/A | BB19: =VLOOKUP($AW19,$AM$19:$AV$28,6,FALSE) -> #N/A | BC19: =VLOOKUP($AW19,$AM$19:$AV$28,7,FALSE) -> #N/A | BD19: =VLOOKUP($AW19,$AM$19:$AV$28,8,FALSE) -> #N/A | BE19: =VLOOKUP($AW19,$AM$19:$AV$28,9,FALSE) -> #N/A | BF19: =VLOOKUP($AW19,$AM$19:$AV$28,10,FALSE) -> #N/A | BH19: =IF($BI19<>"",BH18+1,"") | BI19: =IF($I19<>"",G19,"") | BJ19: =IF(ISNA($AB19<>""),"",$I19) -> 0 | BK19: =IF(AB19=0,"",IF(ISNA(AB19),"",IF($AB19<>"",AB19,""))) | BL19: =IF(ISNA(AB19),"",IF($AB19<>"",AF19,"")) | BM19: =IF(AH19<>"",AH19,"") | BN19: =IF(AJ19<>"",AJ19,"") | BO19: =IF($BP19<>"",BO18+1,"") | BP19: =IF(BK19<>"", BI19,"") | BQ19: =IF(BL19<>"", BJ19,"") | BR19: =IF(BJ19<>"", BK19,"") | BS19: =IF(BK19<>"", BL19,"") | BT19: =IF(BK19<>"", BM19,"") | BU19: =IF(BK19<>"", BN19,"") | BV19: 1 | BW19: =VLOOKUP($BV19,$BO$19:$BR$28,2,FALSE) -> #N/A | BX19: =VLOOKUP($BV19,$BO$19:$BU$28,3,FALSE) -> #N/A | BY19: =VLOOKUP($BV19,$BO$19:$BU$28,4,FALSE) -> #N/A | BZ19: =VLOOKUP($BV19,$BO$19:$BU$28,5,FALSE) -> #N/A | CA19: =VLOOKUP($BV19,$BO$19:$BU$28,6,FALSE) -> #N/A | CB19: =VLOOKUP($BV19,$BO$19:$BU$28,7,FALSE) -> #N/A | CH19: =IF(ISNA(BD19),"",BD19)
AM20: =IF($AN20<>"",MAX(AM$18:AM19)+1,"") | AN20: =IF(AP20=0,"",IF(ISNA(AP20),"",IF($I20<>"",G20,""))) | AO20: =IF(AP20=0,"",IF(ISNA(AP20),"",IF($I20<>"",I20,""))) | AP20: =IF($I20<>"",J20,"") | AQ20: =IF($I20<>"",L20,"") | AR20: =IF($I20<>"",O20,"") | AS20: =IF($I20<>"",Q20,"") | AT20: =IF($I20<>"",T20,"") | AU20: =IF($I20<>"",X20,"") | AV20: =IF($I20<>"",Z20,"") | AW20: 2 | AX20: =VLOOKUP($AW20,$AM$19:$AV$28,2,FALSE) -> #N/A | AY20: =VLOOKUP($AW20,$AM$19:$AV$28,3,FALSE) -> #N/A | AZ20: =VLOOKUP($AW20,$AM$19:$AV$28,4,FALSE) -> #N/A | BA20: =VLOOKUP($AW20,$AM$19:$AV$28,5,FALSE) -> #N/A | BB20: =VLOOKUP($AW20,$AM$19:$AV$28,6,FALSE) -> #N/A | BC20: =VLOOKUP($AW20,$AM$19:$AV$28,7,FALSE) -> #N/A | BD20: =VLOOKUP($AW20,$AM$19:$AV$28,8,FALSE) -> #N/A | BE20: =VLOOKUP($AW20,$AM$19:$AV$28,9,FALSE) -> #N/A | BF20: =VLOOKUP($AW20,$AM$19:$AV$28,10,FALSE) -> #N/A | BH20: =IF($BI20<>"",MAX(BH$18:BH19)+1,"") | BI20: =IF($I20<>"",G20,"") | BJ20: =IF(ISNA($AB20<>""),"",$I20) -> 0 | BK20: =IF(AB20=0,"",IF(ISNA(AB20),"",IF($AB20<>"",AB20,""))) | BL20: =IF(ISNA(AB20),"",IF($AB20<>"",AF20,"")) | BM20: =IF(AH20<>"",AH20,"") | BN20: =IF(AJ20<>"",AJ20,"") | BO20: =IF($BP20<>"",MAX(BO$18:BO19)+1,"") | BP20: =IF(BK20<>"", BI20,"") | BQ20: =IF(BL20<>"", BJ20,"") | BR20: =IF(BJ20<>"", BK20,"") | BS20: =IF(BK20<>"", BL20,"") | BT20: =IF(BK20<>"", BM20,"") | BU20: =IF(BK20<>"", BN20,"") | BV20: 2 | BW20: =VLOOKUP($BV20,$BO$19:$BR$28,2,FALSE) -> #N/A | BX20: =VLOOKUP($BV20,$BO$19:$BU$28,3,FALSE) -> #N/A | BY20: =VLOOKUP($BV20,$BO$19:$BU$28,4,FALSE) -> #N/A | BZ20: =VLOOKUP($BV20,$BO$19:$BU$28,5,FALSE) -> #N/A | CA20: =VLOOKUP($BV20,$BO$19:$BU$28,6,FALSE) -> #N/A | CB20: =VLOOKUP($BV20,$BO$19:$BU$28,7,FALSE) -> #N/A | CH20: =IF(ISNA(BD20),"",BD20)
AM21: =IF($AN21<>"",MAX(AM$18:AM20)+1,"") | AN21: =IF(AP21=0,"",IF(ISNA(AP21),"",IF($I21<>"",G21,""))) | AO21: =IF(AP21=0,"",IF(ISNA(AP21),"",IF($I21<>"",I21,""))) | AP21: =IF($I21<>"",J21,"") | AQ21: =IF($I21<>"",L21,"") | AR21: =IF($I21<>"",O21,"") | AS21: =IF($I21<>"",Q21,"") | AT21: =IF($I21<>"",T21,"") | AU21: =IF($I21<>"",X21,"") | AV21: =IF($I21<>"",Z21,"") | AW21: 3 | AX21: =VLOOKUP($AW21,$AM$19:$AV$28,2,FALSE) -> #N/A | AY21: =VLOOKUP($AW21,$AM$19:$AV$28,3,FALSE) -> #N/A | AZ21: =VLOOKUP($AW21,$AM$19:$AV$28,4,FALSE) -> #N/A | BA21: =VLOOKUP($AW21,$AM$19:$AV$28,5,FALSE) -> #N/A | BB21: =VLOOKUP($AW21,$AM$19:$AV$28,6,FALSE) -> #N/A | BC21: =VLOOKUP($AW21,$AM$19:$AV$28,7,FALSE) -> #N/A | BD21: =VLOOKUP($AW21,$AM$19:$AV$28,8,FALSE) -> #N/A | BE21: =VLOOKUP($AW21,$AM$19:$AV$28,9,FALSE) -> #N/A | BF21: =VLOOKUP($AW21,$AM$19:$AV$28,10,FALSE) -> #N/A | BH21: =IF($BI21<>"",MAX(BH$18:BH20)+1,"") | BI21: =IF($I21<>"",G21,"") | BJ21: =IF(ISNA($AB21<>""),"",$I21) -> 0 | BK21: =IF(AB21=0,"",IF(ISNA(AB21),"",IF($AB21<>"",AB21,""))) | BL21: =IF(ISNA(AB21),"",IF($AB21<>"",AF21,"")) | BM21: =IF(AH21<>"",AH21,"") | BN21: =IF(AJ21<>"",AJ21,"") | BO21: =IF($BP21<>"",MAX(BO$18:BO20)+1,"") | BP21: =IF(BK21<>"", BI21,"") | BQ21: =IF(BL21<>"", BJ21,"") | BR21: =IF(BJ21<>"", BK21,"") | BS21: =IF(BK21<>"", BL21,"") | BT21: =IF(BK21<>"", BM21,"") | BU21: =IF(BK21<>"", BN21,"") | BV21: 3 | BW21: =VLOOKUP($BV21,$BO$19:$BR$28,2,FALSE) -> #N/A | BX21: =VLOOKUP($BV21,$BO$19:$BU$28,3,FALSE) -> #N/A | BY21: =VLOOKUP($BV21,$BO$19:$BU$28,4,FALSE) -> #N/A | BZ21: =VLOOKUP($BV21,$BO$19:$BU$28,5,FALSE) -> #N/A | CA21: =VLOOKUP($BV21,$BO$19:$BU$28,6,FALSE) -> #N/A | CB21: =VLOOKUP($BV21,$BO$19:$BU$28,7,FALSE) -> #N/A | CH21: =IF(ISNA(BD21),"",BD21)
AM22: =IF($AN22<>"",MAX(AM$18:AM21)+1,"") | AN22: =IF(AP22=0,"",IF(ISNA(AP22),"",IF($I22<>"",G22,""))) | AO22: =IF(AP22=0,"",IF(ISNA(AP22),"",IF($I22<>"",I22,""))) | AP22: =IF($I22<>"",J22,"") | AQ22: =IF($I22<>"",L22,"") | AR22: =IF($I22<>"",O22,"") | AS22: =IF($I22<>"",Q22,"") | AT22: =IF($I22<>"",T22,"") | AU22: =IF($I22<>"",X22,"") | AV22: =IF($I22<>"",Z22,"") | AW22: 4 | AX22: =VLOOKUP($AW22,$AM$19:$AV$28,2,FALSE) -> #N/A | AY22: =VLOOKUP($AW22,$AM$19:$AV$28,3,FALSE) -> #N/A | AZ22: =VLOOKUP($AW22,$AM$19:$AV$28,4,FALSE) -> #N/A | BA22: =VLOOKUP($AW22,$AM$19:$AV$28,5,FALSE) -> #N/A | BB22: =VLOOKUP($AW22,$AM$19:$AV$28,6,FALSE) -> #N/A | BC22: =VLOOKUP($AW22,$AM$19:$AV$28,7,FALSE) -> #N/A | BD22: =VLOOKUP($AW22,$AM$19:$AV$28,8,FALSE) -> #N/A | BE22: =VLOOKUP($AW22,$AM$19:$AV$28,9,FALSE) -> #N/A | BF22: =VLOOKUP($AW22,$AM$19:$AV$28,10,FALSE) -> #N/A | BH22: =IF($BI22<>"",MAX(BH$18:BH21)+1,"") | BI22: =IF($I22<>"",G22,"") | BJ22: =IF(ISNA($AB22<>""),"",$I22) -> 0 | BK22: =IF(AB22=0,"",IF(ISNA(AB22),"",IF($AB22<>"",AB22,""))) | BL22: =IF(ISNA(AB22),"",IF($AB22<>"",AF22,"")) | BM22: =IF(AH22<>"",AH22,"") | BN22: =IF(AJ22<>"",AJ22,"") | BO22: =IF($BP22<>"",MAX(BO$18:BO21)+1,"") | BP22: =IF(BK22<>"", BI22,"") | BQ22: =IF(BL22<>"", BJ22,"") | BR22: =IF(BJ22<>"", BK22,"") | BS22: =IF(BK22<>"", BL22,"") | BT22: =IF(BK22<>"", BM22,"") | BU22: =IF(BK22<>"", BN22,"") | BV22: 4 | BW22: =VLOOKUP($BV22,$BO$19:$BR$28,2,FALSE) -> #N/A | BX22: =VLOOKUP($BV22,$BO$19:$BU$28,3,FALSE) -> #N/A | BY22: =VLOOKUP($BV22,$BO$19:$BU$28,4,FALSE) -> #N/A | BZ22: =VLOOKUP($BV22,$BO$19:$BU$28,5,FALSE) -> #N/A | CA22: =VLOOKUP($BV22,$BO$19:$BU$28,6,FALSE) -> #N/A | CB22: =VLOOKUP($BV22,$BO$19:$BU$28,7,FALSE) -> #N/A | CH22: =IF(ISNA(BD22),"",BD22)
AM23: =IF($AN23<>"",MAX(AM$18:AM22)+1,"") | AN23: =IF(AP23=0,"",IF(ISNA(AP23),"",IF($I23<>"",G23,""))) | AO23: =IF(AP23=0,"",IF(ISNA(AP23),"",IF($I23<>"",I23,""))) | AP23: =IF($I23<>"",J23,"") | AQ23: =IF($I23<>"",L23,"") | AR23: =IF($I23<>"",O23,"") | AS23: =IF($I23<>"",Q23,"") | AT23: =IF($I23<>"",T23,"") | AU23: =IF($I23<>"",X23,"") | AV23: =IF($I23<>"",Z23,"") | AW23: 5 | AX23: =VLOOKUP($AW23,$AM$19:$AV$28,2,FALSE) -> #N/A | AY23: =VLOOKUP($AW23,$AM$19:$AV$28,3,FALSE) -> #N/A | AZ23: =VLOOKUP($AW23,$AM$19:$AV$28,4,FALSE) -> #N/A | BA23: =VLOOKUP($AW23,$AM$19:$AV$28,5,FALSE) -> #N/A | BB23: =VLOOKUP($AW23,$AM$19:$AV$28,6,FALSE) -> #N/A | BC23: =VLOOKUP($AW23,$AM$19:$AV$28,7,FALSE) -> #N/A | BD23: =VLOOKUP($AW23,$AM$19:$AV$28,8,FALSE) -> #N/A | BE23: =VLOOKUP($AW23,$AM$19:$AV$28,9,FALSE) -> #N/A | BF23: =VLOOKUP($AW23,$AM$19:$AV$28,10,FALSE) -> #N/A | BH23: =IF($BI23<>"",MAX(BH$18:BH22)+1,"") | BI23: =IF($I23<>"",G23,"") | BJ23: =IF(ISNA($AB23<>""),"",$I23) -> 0 | BK23: =IF(AB23=0,"",IF(ISNA(AB23),"",IF($AB23<>"",AB23,""))) | BL23: =IF(ISNA(AB23),"",IF($AB23<>"",AF23,"")) | BM23: =IF(AH23<>"",AH23,"") | BN23: =IF(AJ23<>"",AJ23,"") | BO23: =IF($BP23<>"",MAX(BO$18:BO22)+1,"") | BP23: =IF(BK23<>"", BI23,"") | BQ23: =IF(BL23<>"", BJ23,"") | BR23: =IF(BJ23<>"", BK23,"") | BS23: =IF(BK23<>"", BL23,"") | BT23: =IF(BK23<>"", BM23,"") | BU23: =IF(BK23<>"", BN23,"") | BV23: 5 | BW23: =VLOOKUP($BV23,$BO$19:$BR$28,2,FALSE) -> #N/A | BX23: =VLOOKUP($BV23,$BO$19:$BU$28,3,FALSE) -> #N/A | BY23: =VLOOKUP($BV23,$BO$19:$BU$28,4,FALSE) -> #N/A | BZ23: =VLOOKUP($BV23,$BO$19:$BU$28,5,FALSE) -> #N/A | CA23: =VLOOKUP($BV23,$BO$19:$BU$28,6,FALSE) -> #N/A | CB23: =VLOOKUP($BV23,$BO$19:$BU$28,7,FALSE) -> #N/A | CH23: =IF(ISNA(BD23),"",BD23)
